Workbook
Name Registros: ABA!$A$13:$AP$500
Name Tentativas: ABA!$A$10:$AP$500

Sheet ABA
A1: PLANILHA DE REGISTRO DOS ATENDIMENTOS | P1: LEGENDA | AT1: Parâmetros
P2: Nota | Q2: Peso | R2: Descrição
P3: A | Q3: 1 | R3: Sem auxilio | AU3: Período (*) | BB3: Recurso (-) | BI3: Sequência necessária para adquirir (+)
D4: Paciente: | P4: B+ | Q4: 0.7 | R4: Com menos ajuda | AU4: Todo o período | BB4: Esperar | BI4: 3
D5: Responsável: | P5: B- | Q5: 0.5 | R5: Com mais ajuda
D6: Observação: | P6: C | Q6: 0 | R6: Não realizou
A9: Habilidade de curto prazo | AT9: ="Análises "&A9 -> Análises Habilidade de curto prazo | CB9: Progresso segmentado por recurso | CM9: Adquirimento de recurso
B10: Vinculo Emocional | F10: Contato Visual | J10: Permanecer sentado na cadeira | N10: Esperar | R10: Seguir instruções de um passo | AP10: % | AQ10: Média Geral | CM10: Data | CN10: =IF(XLOOKUP("Sim",CN13:CN500,CN13:CN500,,0)="Sim","Recurso Adquirido","Não Adquirido") -> Recurso Adquirido | CO10: =IF(XLOOKUP("Sim",CO13:CO500,CO13:CO500,,0)="Sim","Recurso Adquirido","Não Adquirido") -> Não Adquirido | CP10: =IF(XLOOKUP("Sim",CP13:CP500,CP13:CP500,,0)="Sim","Recurso Adquirido","Não Adquirido") -> Não Adquirido | CQ10: =IF(XLOOKUP("Sim",CQ13:CQ500,CQ13:CQ500,,0)="Sim","Recurso Adquirido","Não Adquirido") -> Recurso Adquirido | CR10: =IF(XLOOKUP("Sim",CR13:CR500,CR13:CR500,,0)="Sim","Recurso Adquirido","Não Adquirido") -> Recurso Adquirido | CS10: =IF(XLOOKUP("Sim",CS13:CS500,CS13:CS500,,0)="Sim","Recurso Adquirido","Não Adquirido") -> Não Adquirido | CT10: =IF(XLOOKUP("Sim",CT13:CT500,CT13:CT500,,0)="Sim","Recurso Adquirido","Não Adquirido") -> Não Adquirido | CU10: =IF(XLOOKUP("Sim",CU13:CU500,CU13:CU500,,0)="Sim","Recurso Adquirido","Não Adquirido") -> Não Adquirido | ... CW10: =IF(XLOOKUP("Sim",CW13:CW500,CW13:CW500,,0)="Sim","Recurso Adquirido","Não Adquirido") -> Não Adquirido | DB10: Base para os gráficos
A11: Peso do recurso | AQ11: =IFERROR(AVERAGE(AP:AP),0) -> 0.84738889 | DU11: Está espelhado contra os lançamentos
A12: Data | B12: =$P$3 -> A | C12: =$P$4 -> B+ | D12: =$P$5 -> B- | E12: =$P$6 -> C | F12: =$P$3 -> A | G12: =$P$4 -> B+ | H12: =$P$5 -> B- | I12: =$P$6 -> C | J12: =$P$3 -> A | K12: =$P$4 -> B+ | L12: =$P$5 -> B- | M12: =$P$6 -> C | N12: =$P$3 -> A | O12: =$P$4 -> B+ | P12: =$P$5 -> B- | Q12: =$P$6 -> C | R12: =$P$3 -> A | S12: =$P$4 -> B+ | T12: =$P$5 -> B- | U12: =$P$6 -> C | V12: =$P$3 -> A | W12: =$P$4 -> B+ | X12: =$P$5 -> B- | Y12: =$P$6 -> C | Z12: =$P$3 -> A | AA12: =$P$4 -> B+ | AB12: =$P$5 -> B- | AC12: =$P$6 -> C | AD12: =$P$3 -> A | AE12: =$P$4 -> B+ | AF12: =$P$5 -> B- | AG12: =$P$6 -> C | AH12: =$P$3 -> A | AI12: =$P$4 -> B+ | AJ12: =$P$5 -> B- | AK12: =$P$6 -> C | AL12: =$P$3 -> A | AM12: =$P$4 -> B+ | AN12: =$P$5 -> B- | AO12: =$P$6 -> C | CB12: Data | CC12: =$B$10 -> Vinculo Emocional | CD12: =$F$10 -> Contato Visual | CE12: =$J$10 -> Permanecer sentado na cadeira | CF12: =$N$10 -> Esperar | CG12: =$R$10 -> Seguir instruções de um passo | CH12: =$V$10 | CI12: =$Z$10 | CJ12: =$AD$10 | CK12: =$AH$10 | CL12: =$AL$10 | CN12: =$B$10 -> Vinculo Emocional | CO12: =$F$10 -> Contato Visual | CP12: =$J$10 -> Permanecer sentado na cadeira | CQ12: =$N$10 -> Esperar | CR12: =$R$10 -> Seguir instruções de um passo | CS12: =$V$10 | CT12: =$Z$10 | CU12: =$AD$10 | CV12: =$AH$10 | CW12: =$AL$10 | DU12: Lançamento | DV12: Mês | DW12: Num Mês
A13: 45658 | F13: 1 | G13: 3 | K13: 2 | L13: 1 | N13: 1 | AP13: =IFERROR(AVERAGE(CC13,CD13,CE13,CF13,CG13,CH13,CI13,CJ13,CK13,CL13),"") -> 0.80277778 | CB13: =A13 -> 45658 | CC13: =IFERROR(((B13*(IF(B$11="",INDEX($P$3:$Q$6,MATCH($B$12,$P$3:$P$6,0),2),B$11)))+(C13*(IF(C$11="",INDEX($P$3:$Q$6,MATCH($C$12,$P$3:$P$6,0),2),C$11)))+(D13*IF(D$11="",INDEX($P$3:$Q$6,MATCH($D$12,$P$3:$P$6,0),2),D$11))+(E13*IF(E$11="",INDEX($P$3:$Q$6,MATCH($E$12,$P$3:$P$6,0),2),E$11)))/SUM(B13:E13),"") | CD13: =IFERROR(((F13*(IF(F$11="",INDEX($P$3:$Q$6,MATCH($B$12,$P$3:$P$6,0),2),F$11)))+(G13*(IF(G$11="",INDEX($P$3:$Q$6,MATCH($C$12,$P$3:$P$6,0),2),G$11)))+(H13*IF(H$11="",INDEX($P$3:$Q$6,MATCH($D$12,$P$3:$P$6,0),2),H$11))+(I13*IF(I$11="",INDEX($P$3:$Q$6,MATCH($E$12,$P$3:$P$6,0),2),I$11)))/SUM(F13:I13),"") -> 0.775 | CE13: =IFERROR(((J13*(IF(J$11="",INDEX($P$3:$Q$6,MATCH($B$12,$P$3:$P$6,0),2),J$11)))+(K13*(IF(K$11="",INDEX($P$3:$Q$6,MATCH($C$12,$P$3:$P$6,0),2),K$11)))+(L13*IF(L$11="",INDEX($P$3:$Q$6,MATCH($D$12,$P$3:$P$6,0),2),L$11))+(M13*IF(M$11="",INDEX($P$3:$Q$6,MATCH($E$12,$P$3:$P$6,0),2),M$11)))/SUM(J13:M13),"") -> 0.63333333 | CF13: =IFERROR(((N13*(IF(N$11="",INDEX($P$3:$Q$6,MATCH($B$12,$P$3:$P$6,0),2),N$11)))+(O13*(IF(O$11="",INDEX($P$3:$Q$6,MATCH($C$12,$P$3:$P$6,0),2),O$11)))+(P13*IF(P$11="",INDEX($P$3:$Q$6,MATCH($D$12,$P$3:$P$6,0),2),P$11))+(Q13*IF(Q$11="",INDEX($P$3:$Q$6,MATCH($E$12,$P$3:$P$6,0),2),Q$11)))/SUM(N13:Q13),"") -> 1 | CG13: =IFERROR(((R13*(IF(R$11="",INDEX($P$3:$Q$6,MATCH($B$12,$P$3:$P$6,0),2),R$11)))+(S13*(IF(S$11="",INDEX($P$3:$Q$6,MATCH($C$12,$P$3:$P$6,0),2),S$11)))+(T13*IF(T$11="",INDEX($P$3:$Q$6,MATCH($D$12,$P$3:$P$6,0),2),T$11))+(U13*IF(U$11="",INDEX($P$3:$Q$6,MATCH($E$12,$P$3:$P$6,0),2),U$11)))/SUM(R13:U13),"") | CH13: =IFERROR(((V13*(IF(V$11="",INDEX($P$3:$Q$6,MATCH($B$12,$P$3:$P$6,0),2),V$11)))+(W13*(IF(W$11="",INDEX($P$3:$Q$6,MATCH($C$12,$P$3:$P$6,0),2),W$11)))+(X13*IF(X$11="",INDEX($P$3:$Q$6,MATCH($D$12,$P$3:$P$6,0),2),X$11))+(Y13*IF(Y$11="",INDEX($P$3:$Q$6,MATCH($E$12,$P$3:$P$6,0),2),Y$11)))/SUM(V13:Y13),"") | CI13: =IFERROR(((Z13*(IF(Z$11="",INDEX($P$3:$Q$6,MATCH($B$12,$P$3:$P$6,0),2),Z$11)))+(AA13*(IF(AA$11="",INDEX($P$3:$Q$6,MATCH($C$12,$P$3:$P$6,0),2),AA$11)))+(AB13*IF(AB$11="",INDEX($P$3:$Q$6,MATCH($D$12,$P$3:$P$6,0),2),AB$11))+(AC13*IF(AC$11="",INDEX($P$3:$Q$6,MATCH($E$12,$P$3:$P$6,0),2),AC$11)))/SUM(Z13:AC13),"") | CJ13: =IFERROR(((AD13*(IF(AD$11="",INDEX($P$3:$Q$6,MATCH($B$12,$P$3:$P$6,0),2),AD$11)))+(AE13*(IF(AE$11="",INDEX($P$3:$Q$6,MATCH($C$12,$P$3:$P$6,0),2),AE$11)))+(AF13*IF(AF$11="",INDEX($P$3:$Q$6,MATCH($D$12,$P$3:$P$6,0),2),AF$11))+(AG13*IF(AG$11="",INDEX($P$3:$Q$6,MATCH($E$12,$P$3:$P$6,0),2),L$11)))/SUM(AD13:AG13),"") | CK13: =IFERROR(((AH13*(IF(AH$11="",INDEX($P$3:$Q$6,MATCH($B$12,$P$3:$P$6,0),2),AH$11)))+(AI13*(IF(AI$11="",INDEX($P$3:$Q$6,MATCH($C$12,$P$3:$P$6,0),2),AI$11)))+(AJ13*IF(AJ$11="",INDEX($P$3:$Q$6,MATCH($D$12,$P$3:$P$6,0),2),AJ$11))+(AK13*IF(AK$11="",INDEX($P$3:$Q$6,MATCH($E$12,$P$3:$P$6,0),2),AK$11)))/SUM(AH13:AK13),"") | CL13: =IFERROR(((AL13*(IF(AL$11="",INDEX($P$3:$Q$6,MATCH($B$12,$P$3:$P$6,0),2),AL$11)))+(AM13*(IF(AM$11="",INDEX($P$3:$Q$6,MATCH($C$12,$P$3:$P$6,0),2),AM$11)))+(AN13*IF(AN$11="",INDEX($P$3:$Q$6,MATCH($D$12,$P$3:$P$6,0),2),AN$11))+(AO13*IF(AO$11="",INDEX($P$3:$Q$6,MATCH($E$12,$P$3:$P$6,0),2),AO$11)))/SUM(AL13:AO13),"") | CM13: =A13 -> 45658 | CN13: {=IF(AND(SUM(INDIRECT("CC"&ROW(CC14) - $BI$4&":CC" & ROW(CC13)))=$BI$4,$CM13<>""),"Sim","")} | CO13: =IF(AND(SUM(INDIRECT("CD"&ROW(CD14) - $BI$4&":CD" & ROW(CD13)))=$BI$4,$CM13<>""),"Sim","") | CP13: =IF(AND(SUM(INDIRECT("CE"&ROW(CE14) - $BI$4&":CE" & ROW(CE13)))=$BI$4,$CM13<>""),"Sim","") | CQ13: =IF(AND(SUM(INDIRECT("CF"&ROW(CF14) - $BI$4&":CF" & ROW(CF13)))=$BI$4,$CM13<>""),"Sim","") | CR13: =IF(AND(SUM(INDIRECT("CG"&ROW(CG14) - $BI$4&":CG" & ROW(CG13)))=$BI$4,$CM13<>""),"Sim","") | CS13: =IF(AND(SUM(INDIRECT("CH"&ROW(CH14) - $BI$4&":CH" & ROW(CH13)))=$BI$4,$CM13<>""),"Sim","") | CT13: =IF(AND(SUM(INDIRECT("CI"&ROW(CI14) - $BI$4&":CI" & ROW(CI13)))=$BI$4,$CM13<>""),"Sim","") | CU13: =IF(AND(SUM(INDIRECT("CJ"&ROW(CJ14) - $BI$4&":CJ" & ROW(CJ13)))=$BI$4,$CM13<>""),"Sim","") | CV13: =IF(AND(SUM(INDIRECT("CK"&ROW(CK14) - $BI$4&":CK" & ROW(CK13)))=$BI$4,$CM13<>""),"Sim","") | CW13: =IF(AND(SUM(INDIRECT("CL"&ROW(CL14) - $BI$4&":CL" & ROW(CL13)))=$BI$4,$CM13<>""),"Sim","") | DB13: =IF(DD13<>"","Jan.","") -> Jan. | DC13: 1 | DD13: =IFERROR(__xludf.DUMMYFUNCTION("IFERROR(AVERAGE(FILTER(INDIRECT(ADDRESS(13, (MATCH($BB$4, $12:$12, 0))) & "":"" & ADDRESS(1000, (MATCH($BB$4, $12:$12, 0)))), $DW$13:$DW$500 = DC13,$A$13:$A$500 >= $DQ$25,$A$13:$A$500 <= $DQ$26)),"""") "),1.0) -> 1 | DF13: Habilidade | DG13: Média Geral | DI13: Recurso | DJ13: Status | DK13: Atingiu | DM13: Habilidade | DN13: Média Geral | DP13: Todo o período | DQ13: 2 | DU13: =A13 -> 45658 | DV13: =ABA!$A13 -> 45658 | DW13: =IF(DV13<>"",MONTH(DV13),"") -> 1
A14: 45689 | B14: 1 | G14: 4 | J14: 4 | L14: 1 | N14: 1 | R14: 1 | AP14: =IFERROR(AVERAGE(CC14,CD14,CE14,CF14,CG14,CH14,CI14,CJ14,CK14,CL14),"") -> 0.92 | CB14: =A14 -> 45689 | CC14: =IFERROR(((B14*(IF(B$11="",INDEX($P$3:$Q$6,MATCH($B$12,$P$3:$P$6,0),2),B$11)))+(C14*(IF(C$11="",INDEX($P$3:$Q$6,MATCH($C$12,$P$3:$P$6,0),2),C$11)))+(D14*IF(D$11="",INDEX($P$3:$Q$6,MATCH($D$12,$P$3:$P$6,0),2),D$11))+(E14*IF(E$11="",INDEX($P$3:$Q$6,MATCH($E$12,$P$3:$P$6,0),2),E$11)))/SUM(B14:E14),"") -> 1 | CD14: =IFERROR(((F14*(IF(F$11="",INDEX($P$3:$Q$6,MATCH($B$12,$P$3:$P$6,0),2),F$11)))+(G14*(IF(G$11="",INDEX($P$3:$Q$6,MATCH($C$12,$P$3:$P$6,0),2),G$11)))+(H14*IF(H$11="",INDEX($P$3:$Q$6,MATCH($D$12,$P$3:$P$6,0),2),H$11))+(I14*IF(I$11="",INDEX($P$3:$Q$6,MATCH($E$12,$P$3:$P$6,0),2),I$11)))/SUM(F14:I14),"") -> 0.7 | CE14: =IFERROR(((J14*(IF(J$11="",INDEX($P$3:$Q$6,MATCH($B$12,$P$3:$P$6,0),2),J$11)))+(K14*(IF(K$11="",INDEX($P$3:$Q$6,MATCH($C$12,$P$3:$P$6,0),2),K$11)))+(L14*IF(L$11="",INDEX($P$3:$Q$6,MATCH($D$12,$P$3:$P$6,0),2),L$11))+(M14*IF(M$11="",INDEX($P$3:$Q$6,MATCH($E$12,$P$3:$P$6,0),2),M$11)))/SUM(J14:M14),"") -> 0.9 | CF14: =IFERROR(((N14*(IF(N$11="",INDEX($P$3:$Q$6,MATCH($B$12,$P$3:$P$6,0),2),N$11)))+(O14*(IF(O$11="",INDEX($P$3:$Q$6,MATCH($C$12,$P$3:$P$6,0),2),O$11)))+(P14*IF(P$11="",INDEX($P$3:$Q$6,MATCH($D$12,$P$3:$P$6,0),2),P$11))+(Q14*IF(Q$11="",INDEX($P$3:$Q$6,MATCH($E$12,$P$3:$P$6,0),2),Q$11)))/SUM(N14:Q14),"") -> 1 | CG14: =IFERROR(((R14*(IF(R$11="",INDEX($P$3:$Q$6,MATCH($B$12,$P$3:$P$6,0),2),R$11)))+(S14*(IF(S$11="",INDEX($P$3:$Q$6,MATCH($C$12,$P$3:$P$6,0),2),S$11)))+(T14*IF(T$11="",INDEX($P$3:$Q$6,MATCH($D$12,$P$3:$P$6,0),2),T$11))+(U14*IF(U$11="",INDEX($P$3:$Q$6,MATCH($E$12,$P$3:$P$6,0),2),U$11)))/SUM(R14:U14),"") -> 1 | CH14: =IFERROR(((V14*(IF(V$11="",INDEX($P$3:$Q$6,MATCH($B$12,$P$3:$P$6,0),2),V$11)))+(W14*(IF(W$11="",INDEX($P$3:$Q$6,MATCH($C$12,$P$3:$P$6,0),2),W$11)))+(X14*IF(X$11="",INDEX($P$3:$Q$6,MATCH($D$12,$P$3:$P$6,0),2),X$11))+(Y14*IF(Y$11="",INDEX($P$3:$Q$6,MATCH($E$12,$P$3:$P$6,0),2),Y$11)))/SUM(V14:Y14),"") | CI14: =IFERROR(((Z14*(IF(Z$11="",INDEX($P$3:$Q$6,MATCH($B$12,$P$3:$P$6,0),2),Z$11)))+(AA14*(IF(AA$11="",INDEX($P$3:$Q$6,MATCH($C$12,$P$3:$P$6,0),2),AA$11)))+(AB14*IF(AB$11="",INDEX($P$3:$Q$6,MATCH($D$12,$P$3:$P$6,0),2),AB$11))+(AC14*IF(AC$11="",INDEX($P$3:$Q$6,MATCH($E$12,$P$3:$P$6,0),2),AC$11)))/SUM(Z14:AC14),"") | CJ14: =IFERROR(((AD14*(IF(AD$11="",INDEX($P$3:$Q$6,MATCH($B$12,$P$3:$P$6,0),2),AD$11)))+(AE14*(IF(AE$11="",INDEX($P$3:$Q$6,MATCH($C$12,$P$3:$P$6,0),2),AE$11)))+(AF14*IF(AF$11="",INDEX($P$3:$Q$6,MATCH($D$12,$P$3:$P$6,0),2),AF$11))+(AG14*IF(AG$11="",INDEX($P$3:$Q$6,MATCH($E$12,$P$3:$P$6,0),2),L$11)))/SUM(AD14:AG14),"") | CK14: =IFERROR(((AH14*(IF(AH$11="",INDEX($P$3:$Q$6,MATCH($B$12,$P$3:$P$6,0),2),AH$11)))+(AI14*(IF(AI$11="",INDEX($P$3:$Q$6,MATCH($C$12,$P$3:$P$6,0),2),AI$11)))+(AJ14*IF(AJ$11="",INDEX($P$3:$Q$6,MATCH($D$12,$P$3:$P$6,0),2),AJ$11))+(AK14*IF(AK$11="",INDEX($P$3:$Q$6,MATCH($E$12,$P$3:$P$6,0),2),AK$11)))/SUM(AH14:AK14),"") | CL14: =IFERROR(((AL14*(IF(AL$11="",INDEX($P$3:$Q$6,MATCH($B$12,$P$3:$P$6,0),2),AL$11)))+(AM14*(IF(AM$11="",INDEX($P$3:$Q$6,MATCH($C$12,$P$3:$P$6,0),2),AM$11)))+(AN14*IF(AN$11="",INDEX($P$3:$Q$6,MATCH($D$12,$P$3:$P$6,0),2),AN$11))+(AO14*IF(AO$11="",INDEX($P$3:$Q$6,MATCH($E$12,$P$3:$P$6,0),2),AO$11)))/SUM(AL14:AO14),"") | CM14: =A14 -> 45689 | CN14: =IF(AND(SUM(INDIRECT("CC"&ROW(CC15) - $BI$4&":CC" & ROW(CC14)))=$BI$4,CM14<>""),"Sim","") | CO14: =IF(AND(SUM(INDIRECT("CD"&ROW(CD15) - $BI$4&":CD" & ROW(CD14)))=$BI$4,$CM14<>""),"Sim","") | CP14: =IF(AND(SUM(INDIRECT("CE"&ROW(CE15) - $BI$4&":CE" & ROW(CE14)))=$BI$4,$CM14<>""),"Sim","") | CQ14: =IF(AND(SUM(INDIRECT("CF"&ROW(CF15) - $BI$4&":CF" & ROW(CF14)))=$BI$4,$CM14<>""),"Sim","") | CR14: =IF(AND(SUM(INDIRECT("CG"&ROW(CG15) - $BI$4&":CG" & ROW(CG14)))=$BI$4,$CM14<>""),"Sim","") | CS14: =IF(AND(SUM(INDIRECT("CH"&ROW(CH15) - $BI$4&":CH" & ROW(CH14)))=$BI$4,$CM14<>""),"Sim","") | CT14: =IF(AND(SUM(INDIRECT("CI"&ROW(CI15) - $BI$4&":CI" & ROW(CI14)))=$BI$4,$CM14<>""),"Sim","") | CU14: =IF(AND(SUM(INDIRECT("CJ"&ROW(CJ15) - $BI$4&":CJ" & ROW(CJ14)))=$BI$4,$CM14<>""),"Sim","") | CV14: =IF(AND(SUM(INDIRECT("CK"&ROW(CK15) - $BI$4&":CK" & ROW(CK14)))=$BI$4,$CM14<>""),"Sim","") | CW14: =IF(AND(SUM(INDIRECT("CL"&ROW(CL15) - $BI$4&":CL" & ROW(CL14)))=$BI$4,$CM14<>""),"Sim","") | DB14: =IF(DD14<>"","Fev.","") -> Fev. | DC14: 2 | DD14: =IFERROR(__xludf.DUMMYFUNCTION("IFERROR(AVERAGE(FILTER(INDIRECT(ADDRESS(13, (MATCH($BB$4, $12:$12, 0))) & "":"" & ADDRESS(1000, (MATCH($BB$4, $12:$12, 0)))), $DW$13:$DW$500 = DC14,$A$13:$A$500 >= $DQ$25,$A$13:$A$500 <= $DQ$26)),"""") "),1.0) -> 1 | DF14: =$B10 -> Vinculo Emocional | DG14: =IFERROR(__xludf.DUMMYFUNCTION("IFERROR(AVERAGE(FILTER(INDIRECT(ADDRESS(13,(MATCH(DF14,$12:$12,0))) & "":"" & ADDRESS(1000, (MATCH(DF14,$12:$12,0)))),$A$13:$A$500 >= $DQ$25,$A$13:$A$500 <= $DQ$26)),"""")"),1.0) -> 1 | DI14: =IF(DK14=1,$B10,"") -> Vinculo Emocional | DJ14: =IF(INDEX($CN$10:$CW$12,1,ROW(BV1))="Recurso Adquirido",INDEX($CN$10:$CW$12,1,ROW(BV1)),"") -> Recurso Adquirido | DK14: =IF(DJ14="Recurso Adquirido",1,"") -> 1 | DM14: =$B10 -> Vinculo Emocional | DN14: =IFERROR(__xludf.DUMMYFUNCTION("IFERROR(AVERAGE(FILTER(INDIRECT(ADDRESS(13, (MATCH(DM14, $12:$12, 0))) & "":"" & ADDRESS(1000, (MATCH(DM14, $12:$12, 0)))), $A$13:$A$500 > (DATE(YEAR((TODAY()-(30*2))),MONTH((TODAY()-(30*2))),1)))),"""") "),"") | DP14: Últimos 6 meses | DQ14: =DATE(YEAR((TODAY()-(150))),MONTH((TODAY()-(150))),1) -> 46082 | DS14: =DATE(YEAR((TODAY()-(30*2))),MONTH((TODAY()-(30*2))),1) -> 46174 | DU14: =A14 -> 45689 | DV14: =ABA!$A14 -> 45689 | DW14: =IF(DV14<>"",MONTH(DV14),"") -> 2
A15: 45717 | B15: 1 | F15: 1 | H15: 2 | I15: 1 | L15: 1 | M15: 3 | N15: 1 | R15: 1 | AP15: =IFERROR(AVERAGE(CC15,CD15,CE15,CF15,CG15,CH15,CI15,CJ15,CK15,CL15),"") -> 0.725 | CB15: =A15 -> 45717 | CC15: =IFERROR(((B15*(IF(B$11="",INDEX($P$3:$Q$6,MATCH($B$12,$P$3:$P$6,0),2),B$11)))+(C15*(IF(C$11="",INDEX($P$3:$Q$6,MATCH($C$12,$P$3:$P$6,0),2),C$11)))+(D15*IF(D$11="",INDEX($P$3:$Q$6,MATCH($D$12,$P$3:$P$6,0),2),D$11))+(E15*IF(E$11="",INDEX($P$3:$Q$6,MATCH($E$12,$P$3:$P$6,0),2),E$11)))/SUM(B15:E15),"") -> 1 | CD15: =IFERROR(((F15*(IF(F$11="",INDEX($P$3:$Q$6,MATCH($B$12,$P$3:$P$6,0),2),F$11)))+(G15*(IF(G$11="",INDEX($P$3:$Q$6,MATCH($C$12,$P$3:$P$6,0),2),G$11)))+(H15*IF(H$11="",INDEX($P$3:$Q$6,MATCH($D$12,$P$3:$P$6,0),2),H$11))+(I15*IF(I$11="",INDEX($P$3:$Q$6,MATCH($E$12,$P$3:$P$6,0),2),I$11)))/SUM(F15:I15),"") -> 0.5 | CE15: =IFERROR(((J15*(IF(J$11="",INDEX($P$3:$Q$6,MATCH($B$12,$P$3:$P$6,0),2),J$11)))+(K15*(IF(K$11="",INDEX($P$3:$Q$6,MATCH($C$12,$P$3:$P$6,0),2),K$11)))+(L15*IF(L$11="",INDEX($P$3:$Q$6,MATCH($D$12,$P$3:$P$6,0),2),L$11))+(M15*IF(M$11="",INDEX($P$3:$Q$6,MATCH($E$12,$P$3:$P$6,0),2),M$11)))/SUM(J15:M15),"") -> 0.125 | CF15: =IFERROR(((N15*(IF(N$11="",INDEX($P$3:$Q$6,MATCH($B$12,$P$3:$P$6,0),2),N$11)))+(O15*(IF(O$11="",INDEX($P$3:$Q$6,MATCH($C$12,$P$3:$P$6,0),2),O$11)))+(P15*IF(P$11="",INDEX($P$3:$Q$6,MATCH($D$12,$P$3:$P$6,0),2),P$11))+(Q15*IF(Q$11="",INDEX($P$3:$Q$6,MATCH($E$12,$P$3:$P$6,0),2),Q$11)))/SUM(N15:Q15),"") -> 1 | CG15: =IFERROR(((R15*(IF(R$11="",INDEX($P$3:$Q$6,MATCH($B$12,$P$3:$P$6,0),2),R$11)))+(S15*(IF(S$11="",INDEX($P$3:$Q$6,MATCH($C$12,$P$3:$P$6,0),2),S$11)))+(T15*IF(T$11="",INDEX($P$3:$Q$6,MATCH($D$12,$P$3:$P$6,0),2),T$11))+(U15*IF(U$11="",INDEX($P$3:$Q$6,MATCH($E$12,$P$3:$P$6,0),2),U$11)))/SUM(R15:U15),"") -> 1 | CH15: =IFERROR(((V15*(IF(V$11="",INDEX($P$3:$Q$6,MATCH($B$12,$P$3:$P$6,0),2),V$11)))+(W15*(IF(W$11="",INDEX($P$3:$Q$6,MATCH($C$12,$P$3:$P$6,0),2),W$11)))+(X15*IF(X$11="",INDEX($P$3:$Q$6,MATCH($D$12,$P$3:$P$6,0),2),X$11))+(Y15*IF(Y$11="",INDEX($P$3:$Q$6,MATCH($E$12,$P$3:$P$6,0),2),Y$11)))/SUM(V15:Y15),"") | CI15: =IFERROR(((Z15*(IF(Z$11="",INDEX($P$3:$Q$6,MATCH($B$12,$P$3:$P$6,0),2),Z$11)))+(AA15*(IF(AA$11="",INDEX($P$3:$Q$6,MATCH($C$12,$P$3:$P$6,0),2),AA$11)))+(AB15*IF(AB$11="",INDEX($P$3:$Q$6,MATCH($D$12,$P$3:$P$6,0),2),AB$11))+(AC15*IF(AC$11="",INDEX($P$3:$Q$6,MATCH($E$12,$P$3:$P$6,0),2),AC$11)))/SUM(Z15:AC15),"") | CJ15: =IFERROR(((AD15*(IF(AD$11="",INDEX($P$3:$Q$6,MATCH($B$12,$P$3:$P$6,0),2),AD$11)))+(AE15*(IF(AE$11="",INDEX($P$3:$Q$6,MATCH($C$12,$P$3:$P$6,0),2),AE$11)))+(AF15*IF(AF$11="",INDEX($P$3:$Q$6,MATCH($D$12,$P$3:$P$6,0),2),AF$11))+(AG15*IF(AG$11="",INDEX($P$3:$Q$6,MATCH($E$12,$P$3:$P$6,0),2),L$11)))/SUM(AD15:AG15),"") | CK15: =IFERROR(((AH15*(IF(AH$11="",INDEX($P$3:$Q$6,MATCH($B$12,$P$3:$P$6,0),2),AH$11)))+(AI15*(IF(AI$11="",INDEX($P$3:$Q$6,MATCH($C$12,$P$3:$P$6,0),2),AI$11)))+(AJ15*IF(AJ$11="",INDEX($P$3:$Q$6,MATCH($D$12,$P$3:$P$6,0),2),AJ$11))+(AK15*IF(AK$11="",INDEX($P$3:$Q$6,MATCH($E$12,$P$3:$P$6,0),2),AK$11)))/SUM(AH15:AK15),"") | CL15: =IFERROR(((AL15*(IF(AL$11="",INDEX($P$3:$Q$6,MATCH($B$12,$P$3:$P$6,0),2),AL$11)))+(AM15*(IF(AM$11="",INDEX($P$3:$Q$6,MATCH($C$12,$P$3:$P$6,0),2),AM$11)))+(AN15*IF(AN$11="",INDEX($P$3:$Q$6,MATCH($D$12,$P$3:$P$6,0),2),AN$11))+(AO15*IF(AO$11="",INDEX($P$3:$Q$6,MATCH($E$12,$P$3:$P$6,0),2),AO$11)))/SUM(AL15:AO15),"") | CM15: =A15 -> 45717 | CN15: =IF(AND(SUM(INDIRECT("CC"&ROW(CC16) - $BI$4&":CC" & ROW(CC15)))=$BI$4,CM15<>""),"Sim","") | CO15: =IF(AND(SUM(INDIRECT("CD"&ROW(CD16) - $BI$4&":CD" & ROW(CD15)))=$BI$4,$CM15<>""),"Sim","") | CP15: =IF(AND(SUM(INDIRECT("CE"&ROW(CE16) - $BI$4&":CE" & ROW(CE15)))=$BI$4,$CM15<>""),"Sim","") | CQ15: =IF(AND(SUM(INDIRECT("CF"&ROW(CF16) - $BI$4&":CF" & ROW(CF15)))=$BI$4,$CM15<>""),"Sim","") -> Sim | CR15: =IF(AND(SUM(INDIRECT("CG"&ROW(CG16) - $BI$4&":CG" & ROW(CG15)))=$BI$4,$CM15<>""),"Sim","") | CS15: =IF(AND(SUM(INDIRECT("CH"&ROW(CH16) - $BI$4&":CH" & ROW(CH15)))=$BI$4,$CM15<>""),"Sim","") | CT15: =IF(AND(SUM(INDIRECT("CI"&ROW(CI16) - $BI$4&":CI" & ROW(CI15)))=$BI$4,$CM15<>""),"Sim","") | CU15: =IF(AND(SUM(INDIRECT("CJ"&ROW(CJ16) - $BI$4&":CJ" & ROW(CJ15)))=$BI$4,$CM15<>""),"Sim","") | CV15: =IF(AND(SUM(INDIRECT("CK"&ROW(CK16) - $BI$4&":CK" & ROW(CK15)))=$BI$4,$CM15<>""),"Sim","") | CW15: =IF(AND(SUM(INDIRECT("CL"&ROW(CL16) - $BI$4&":CL" & ROW(CL15)))=$BI$4,$CM15<>""),"Sim","") | DB15: =IF(DD15<>"","Mar.","") -> Mar. | DC15: 3 | DD15: =IFERROR(__xludf.DUMMYFUNCTION("IFERROR(AVERAGE(FILTER(INDIRECT(ADDRESS(13, (MATCH($BB$4, $12:$12, 0))) & "":"" & ADDRESS(1000, (MATCH($BB$4, $12:$12, 0)))), $DW$13:$DW$500 = DC15,$A$13:$A$500 >= $DQ$25,$A$13:$A$500 <= $DQ$26)),"""") "),1.0) -> 1 | DF15: =$F$10 -> Contato Visual | DG15: =IFERROR(__xludf.DUMMYFUNCTION("IFERROR(AVERAGE(FILTER(INDIRECT(ADDRESS(13,(MATCH(DF15,$12:$12,0))) & "":"" & ADDRESS(1000, (MATCH(DF15,$12:$12,0)))),$A$13:$A$500 >= $DQ$25,$A$13:$A$500 <= $DQ$26)),"""")"),0.559375) -> 0.559375 | DI15: =IF(DK15=1,$F$10,"") | DJ15: =IF(INDEX($CN$10:$CW$12,1,ROW(BV2))="Recurso Adquirido",INDEX($CN$10:$CW$12,1,ROW(BV2)),"") | DK15: =IF(DJ15="Recurso Adquirido",1,"") | DM15: =$F$10 -> Contato Visual | DN15: =IFERROR(__xludf.DUMMYFUNCTION("IFERROR(AVERAGE(FILTER(INDIRECT(ADDRESS(13, (MATCH(DM15, $12:$12, 0))) & "":"" & ADDRESS(1000, (MATCH(DM15, $12:$12, 0)))), $A$13:$A$500 > (DATE(YEAR((TODAY()-(30*2))),MONTH((TODAY()-(30*2))),1)))),"""") "),"") | DP15: {=UNIQUE(IF(A13:A500<>"", YEAR(A13:A500), ""))} -> 2025 | DQ15: =DATE(DP15,1,1) -> 45658 | DU15: =A15 -> 45717 | DV15: =ABA!$A15 -> 45717 | DW15: =IF(DV15<>"",MONTH(DV15),"") -> 3
A16: 45748 | B16: 1 | G16: 3 | I16: 5 | J16: 2 | K16: 3 | M16: 1 | N16: 1 | R16: 1 | AP16: =IFERROR(AVERAGE(CC16,CD16,CE16,CF16,CG16,CH16,CI16,CJ16,CK16,CL16),"") -> 0.78916667 | CB16: =A16 -> 45748 | CC16: =IFERROR(((B16*(IF(B$11="",INDEX($P$3:$Q$6,MATCH($B$12,$P$3:$P$6,0),2),B$11)))+(C16*(IF(C$11="",INDEX($P$3:$Q$6,MATCH($C$12,$P$3:$P$6,0),2),C$11)))+(D16*IF(D$11="",INDEX($P$3:$Q$6,MATCH($D$12,$P$3:$P$6,0),2),D$11))+(E16*IF(E$11="",INDEX($P$3:$Q$6,MATCH($E$12,$P$3:$P$6,0),2),E$11)))/SUM(B16:E16),"") -> 1 | CD16: =IFERROR(((F16*(IF(F$11="",INDEX($P$3:$Q$6,MATCH($B$12,$P$3:$P$6,0),2),F$11)))+(G16*(IF(G$11="",INDEX($P$3:$Q$6,MATCH($C$12,$P$3:$P$6,0),2),G$11)))+(H16*IF(H$11="",INDEX($P$3:$Q$6,MATCH($D$12,$P$3:$P$6,0),2),H$11))+(I16*IF(I$11="",INDEX($P$3:$Q$6,MATCH($E$12,$P$3:$P$6,0),2),I$11)))/SUM(F16:I16),"") -> 0.2625 | CE16: =IFERROR(((J16*(IF(J$11="",INDEX($P$3:$Q$6,MATCH($B$12,$P$3:$P$6,0),2),J$11)))+(K16*(IF(K$11="",INDEX($P$3:$Q$6,MATCH($C$12,$P$3:$P$6,0),2),K$11)))+(L16*IF(L$11="",INDEX($P$3:$Q$6,MATCH($D$12,$P$3:$P$6,0),2),L$11))+(M16*IF(M$11="",INDEX($P$3:$Q$6,MATCH($E$12,$P$3:$P$6,0),2),M$11)))/SUM(J16:M16),"") -> 0.68333333 | CF16: =IFERROR(((N16*(IF(N$11="",INDEX($P$3:$Q$6,MATCH($B$12,$P$3:$P$6,0),2),N$11)))+(O16*(IF(O$11="",INDEX($P$3:$Q$6,MATCH($C$12,$P$3:$P$6,0),2),O$11)))+(P16*IF(P$11="",INDEX($P$3:$Q$6,MATCH($D$12,$P$3:$P$6,0),2),P$11))+(Q16*IF(Q$11="",INDEX($P$3:$Q$6,MATCH($E$12,$P$3:$P$6,0),2),Q$11)))/SUM(N16:Q16),"") -> 1 | CG16: =IFERROR(((R16*(IF(R$11="",INDEX($P$3:$Q$6,MATCH($B$12,$P$3:$P$6,0),2),R$11)))+(S16*(IF(S$11="",INDEX($P$3:$Q$6,MATCH($C$12,$P$3:$P$6,0),2),S$11)))+(T16*IF(T$11="",INDEX($P$3:$Q$6,MATCH($D$12,$P$3:$P$6,0),2),T$11))+(U16*IF(U$11="",INDEX($P$3:$Q$6,MATCH($E$12,$P$3:$P$6,0),2),U$11)))/SUM(R16:U16),"") -> 1 | CH16: =IFERROR(((V16*(IF(V$11="",INDEX($P$3:$Q$6,MATCH($B$12,$P$3:$P$6,0),2),V$11)))+(W16*(IF(W$11="",INDEX($P$3:$Q$6,MATCH($C$12,$P$3:$P$6,0),2),W$11)))+(X16*IF(X$11="",INDEX($P$3:$Q$6,MATCH($D$12,$P$3:$P$6,0),2),X$11))+(Y16*IF(Y$11="",INDEX($P$3:$Q$6,MATCH($E$12,$P$3:$P$6,0),2),Y$11)))/SUM(V16:Y16),"") | CI16: =IFERROR(((Z16*(IF(Z$11="",INDEX($P$3:$Q$6,MATCH($B$12,$P$3:$P$6,0),2),Z$11)))+(AA16*(IF(AA$11="",INDEX($P$3:$Q$6,MATCH($C$12,$P$3:$P$6,0),2),AA$11)))+(AB16*IF(AB$11="",INDEX($P$3:$Q$6,MATCH($D$12,$P$3:$P$6,0),2),AB$11))+(AC16*IF(AC$11="",INDEX($P$3:$Q$6,MATCH($E$12,$P$3:$P$6,0),2),AC$11)))/SUM(Z16:AC16),"") | CJ16: =IFERROR(((AD16*(IF(AD$11="",INDEX($P$3:$Q$6,MATCH($B$12,$P$3:$P$6,0),2),AD$11)))+(AE16*(IF(AE$11="",INDEX($P$3:$Q$6,MATCH($C$12,$P$3:$P$6,0),2),AE$11)))+(AF16*IF(AF$11="",INDEX($P$3:$Q$6,MATCH($D$12,$P$3:$P$6,0),2),AF$11))+(AG16*IF(AG$11="",INDEX($P$3:$Q$6,MATCH($E$12,$P$3:$P$6,0),2),L$11)))/SUM(AD16:AG16),"") | CK16: =IFERROR(((AH16*(IF(AH$11="",INDEX($P$3:$Q$6,MATCH($B$12,$P$3:$P$6,0),2),AH$11)))+(AI16*(IF(AI$11="",INDEX($P$3:$Q$6,MATCH($C$12,$P$3:$P$6,0),2),AI$11)))+(AJ16*IF(AJ$11="",INDEX($P$3:$Q$6,MATCH($D$12,$P$3:$P$6,0),2),AJ$11))+(AK16*IF(AK$11="",INDEX($P$3:$Q$6,MATCH($E$12,$P$3:$P$6,0),2),AK$11)))/SUM(AH16:AK16),"") | CL16: =IFERROR(((AL16*(IF(AL$11="",INDEX($P$3:$Q$6,MATCH($B$12,$P$3:$P$6,0),2),AL$11)))+(AM16*(IF(AM$11="",INDEX($P$3:$Q$6,MATCH($C$12,$P$3:$P$6,0),2),AM$11)))+(AN16*IF(AN$11="",INDEX($P$3:$Q$6,MATCH($D$12,$P$3:$P$6,0),2),AN$11))+(AO16*IF(AO$11="",INDEX($P$3:$Q$6,MATCH($E$12,$P$3:$P$6,0),2),AO$11)))/SUM(AL16:AO16),"") | CM16: =A16 -> 45748 | CN16: =IF(AND(SUM(INDIRECT("CC"&ROW(CC17) - $BI$4&":CC" & ROW(CC16)))=$BI$4,CM16<>""),"Sim","") -> Sim | CO16: =IF(AND(SUM(INDIRECT("CD"&ROW(CD17) - $BI$4&":CD" & ROW(CD16)))=$BI$4,$CM16<>""),"Sim","") | CP16: =IF(AND(SUM(INDIRECT("CE"&ROW(CE17) - $BI$4&":CE" & ROW(CE16)))=$BI$4,$CM16<>""),"Sim","") | CQ16: =IF(AND(SUM(INDIRECT("CF"&ROW(CF17) - $BI$4&":CF" & ROW(CF16)))=$BI$4,$CM16<>""),"Sim","") -> Sim | CR16: =IF(AND(SUM(INDIRECT("CG"&ROW(CG17) - $BI$4&":CG" & ROW(CG16)))=$BI$4,$CM16<>""),"Sim","") -> Sim | CS16: =IF(AND(SUM(INDIRECT("CH"&ROW(CH17) - $BI$4&":CH" & ROW(CH16)))=$BI$4,$CM16<>""),"Sim","") | CT16: =IF(AND(SUM(INDIRECT("CI"&ROW(CI17) - $BI$4&":CI" & ROW(CI16)))=$BI$4,$CM16<>""),"Sim","") | CU16: =IF(AND(SUM(INDIRECT("CJ"&ROW(CJ17) - $BI$4&":CJ" & ROW(CJ16)))=$BI$4,$CM16<>""),"Sim","") | CV16: =IF(AND(SUM(INDIRECT("CK"&ROW(CK17) - $BI$4&":CK" & ROW(CK16)))=$BI$4,$CM16<>""),"Sim","") | CW16: =IF(AND(SUM(INDIRECT("CL"&ROW(CL17) - $BI$4&":CL" & ROW(CL16)))=$BI$4,$CM16<>""),"Sim","") | DB16: =IF(DD16<>"","Abr.","") -> Abr. | DC16: 4 | DD16: =IFERROR(__xludf.DUMMYFUNCTION("IFERROR(AVERAGE(FILTER(INDIRECT(ADDRESS(13, (MATCH($BB$4, $12:$12, 0))) & "":"" & ADDRESS(1000, (MATCH($BB$4, $12:$12, 0)))), $DW$13:$DW$500 = DC16,$A$13:$A$500 >= $DQ$25,$A$13:$A$500 <= $DQ$26)),"""") "),1.0) -> 1 | DF16: =$J$10 -> Permanecer sentado na cadeira | DG16: =IFERROR(__xludf.DUMMYFUNCTION("IFERROR(AVERAGE(FILTER(INDIRECT(ADDRESS(13,(MATCH(DF16,$12:$12,0))) & "":"" & ADDRESS(1000, (MATCH(DF16,$12:$12,0)))),$A$13:$A$500 >= $DQ$25,$A$13:$A$500 <= $DQ$26)),"""")"),0.5854166666666666) -> 0.58541667 | DI16: =IF(DK16=1,$J$10,"") | DJ16: =IF(INDEX($CN$10:$CW$12,1,ROW(BV3))="Recurso Adquirido",INDEX($CN$10:$CW$12,1,ROW(BV3)),"") | DK16: =IF(DJ16="Recurso Adquirido",1,"") | DM16: =$J$10 -> Permanecer sentado na cadeira | DN16: =IFERROR(__xludf.DUMMYFUNCTION("IFERROR(AVERAGE(FILTER(INDIRECT(ADDRESS(13, (MATCH(DM16, $12:$12, 0))) & "":"" & ADDRESS(1000, (MATCH(DM16, $12:$12, 0)))), $A$13:$A$500 > (DATE(YEAR((TODAY()-(30*2))),MONTH((TODAY()-(30*2))),1)))),"""") "),"") | DQ16: =DATE(DP16,1,1) -> 2 | DS16: média geral | DT16: {=IFERROR(AVERAGE(INDIRECT(ADDRESS(2,(MATCH(BB4,$12:$12,0))) & ":" & ADDRESS(1000, (MATCH(BB4,$12:$12,0))))),0)} -> 1 | DU16: =A16 -> 45748 | DV16: =ABA!$A16 -> 45748 | DW16: =IF(DV16<>"",MONTH(DV16),"") -> 4
N17: 1 | R17: 1 | AP17: =IFERROR(AVERAGE(CC17,CD17,CE17,CF17,CG17,CH17,CI17,CJ17,CK17,CL17),"") -> 1 | CB17: =A17 | CC17: =IFERROR(((B17*(IF(B$11="",INDEX($P$3:$Q$6,MATCH($B$12,$P$3:$P$6,0),2),B$11)))+(C17*(IF(C$11="",INDEX($P$3:$Q$6,MATCH($C$12,$P$3:$P$6,0),2),C$11)))+(D17*IF(D$11="",INDEX($P$3:$Q$6,MATCH($D$12,$P$3:$P$6,0),2),D$11))+(E17*IF(E$11="",INDEX($P$3:$Q$6,MATCH($E$12,$P$3:$P$6,0),2),E$11)))/SUM(B17:E17),"") | CD17: =IFERROR(((F17*(IF(F$11="",INDEX($P$3:$Q$6,MATCH($B$12,$P$3:$P$6,0),2),F$11)))+(G17*(IF(G$11="",INDEX($P$3:$Q$6,MATCH($C$12,$P$3:$P$6,0),2),G$11)))+(H17*IF(H$11="",INDEX($P$3:$Q$6,MATCH($D$12,$P$3:$P$6,0),2),H$11))+(I17*IF(I$11="",INDEX($P$3:$Q$6,MATCH($E$12,$P$3:$P$6,0),2),I$11)))/SUM(F17:I17),"") | CE17: =IFERROR(((J17*(IF(J$11="",INDEX($P$3:$Q$6,MATCH($B$12,$P$3:$P$6,0),2),J$11)))+(K17*(IF(K$11="",INDEX($P$3:$Q$6,MATCH($C$12,$P$3:$P$6,0),2),K$11)))+(L17*IF(L$11="",INDEX($P$3:$Q$6,MATCH($D$12,$P$3:$P$6,0),2),L$11))+(M17*IF(M$11="",INDEX($P$3:$Q$6,MATCH($E$12,$P$3:$P$6,0),2),M$11)))/SUM(J17:M17),"") | CF17: =IFERROR(((N17*(IF(N$11="",INDEX($P$3:$Q$6,MATCH($B$12,$P$3:$P$6,0),2),N$11)))+(O17*(IF(O$11="",INDEX($P$3:$Q$6,MATCH($C$12,$P$3:$P$6,0),2),O$11)))+(P17*IF(P$11="",INDEX($P$3:$Q$6,MATCH($D$12,$P$3:$P$6,0),2),P$11))+(Q17*IF(Q$11="",INDEX($P$3:$Q$6,MATCH($E$12,$P$3:$P$6,0),2),Q$11)))/SUM(N17:Q17),"") -> 1 | CG17: =IFERROR(((R17*(IF(R$11="",INDEX($P$3:$Q$6,MATCH($B$12,$P$3:$P$6,0),2),R$11)))+(S17*(IF(S$11="",INDEX($P$3:$Q$6,MATCH($C$12,$P$3:$P$6,0),2),S$11)))+(T17*IF(T$11="",INDEX($P$3:$Q$6,MATCH($D$12,$P$3:$P$6,0),2),T$11))+(U17*IF(U$11="",INDEX($P$3:$Q$6,MATCH($E$12,$P$3:$P$6,0),2),U$11)))/SUM(R17:U17),"") -> 1 | CH17: =IFERROR(((V17*(IF(V$11="",INDEX($P$3:$Q$6,MATCH($B$12,$P$3:$P$6,0),2),V$11)))+(W17*(IF(W$11="",INDEX($P$3:$Q$6,MATCH($C$12,$P$3:$P$6,0),2),W$11)))+(X17*IF(X$11="",INDEX($P$3:$Q$6,MATCH($D$12,$P$3:$P$6,0),2),X$11))+(Y17*IF(Y$11="",INDEX($P$3:$Q$6,MATCH($E$12,$P$3:$P$6,0),2),Y$11)))/SUM(V17:Y17),"") | CI17: =IFERROR(((Z17*(IF(Z$11="",INDEX($P$3:$Q$6,MATCH($B$12,$P$3:$P$6,0),2),Z$11)))+(AA17*(IF(AA$11="",INDEX($P$3:$Q$6,MATCH($C$12,$P$3:$P$6,0),2),AA$11)))+(AB17*IF(AB$11="",INDEX($P$3:$Q$6,MATCH($D$12,$P$3:$P$6,0),2),AB$11))+(AC17*IF(AC$11="",INDEX($P$3:$Q$6,MATCH($E$12,$P$3:$P$6,0),2),AC$11)))/SUM(Z17:AC17),"") | CJ17: =IFERROR(((AD17*(IF(AD$11="",INDEX($P$3:$Q$6,MATCH($B$12,$P$3:$P$6,0),2),AD$11)))+(AE17*(IF(AE$11="",INDEX($P$3:$Q$6,MATCH($C$12,$P$3:$P$6,0),2),AE$11)))+(AF17*IF(AF$11="",INDEX($P$3:$Q$6,MATCH($D$12,$P$3:$P$6,0),2),AF$11))+(AG17*IF(AG$11="",INDEX($P$3:$Q$6,MATCH($E$12,$P$3:$P$6,0),2),L$11)))/SUM(AD17:AG17),"") | CK17: =IFERROR(((AH17*(IF(AH$11="",INDEX($P$3:$Q$6,MATCH($B$12,$P$3:$P$6,0),2),AH$11)))+(AI17*(IF(AI$11="",INDEX($P$3:$Q$6,MATCH($C$12,$P$3:$P$6,0),2),AI$11)))+(AJ17*IF(AJ$11="",INDEX($P$3:$Q$6,MATCH($D$12,$P$3:$P$6,0),2),AJ$11))+(AK17*IF(AK$11="",INDEX($P$3:$Q$6,MATCH($E$12,$P$3:$P$6,0),2),AK$11)))/SUM(AH17:AK17),"") | CL17: =IFERROR(((AL17*(IF(AL$11="",INDEX($P$3:$Q$6,MATCH($B$12,$P$3:$P$6,0),2),AL$11)))+(AM17*(IF(AM$11="",INDEX($P$3:$Q$6,MATCH($C$12,$P$3:$P$6,0),2),AM$11)))+(AN17*IF(AN$11="",INDEX($P$3:$Q$6,MATCH($D$12,$P$3:$P$6,0),2),AN$11))+(AO17*IF(AO$11="",INDEX($P$3:$Q$6,MATCH($E$12,$P$3:$P$6,0),2),AO$11)))/SUM(AL17:AO17),"") | CM17: =A17 | CN17: =IF(AND(SUM(INDIRECT("CC"&ROW(CC18) - $BI$4&":CC" & ROW(CC17)))=$BI$4,CM17<>""),"Sim","") | CO17: =IF(AND(SUM(INDIRECT("CD"&ROW(CD18) - $BI$4&":CD" & ROW(CD17)))=$BI$4,$CM17<>""),"Sim","") | CP17: =IF(AND(SUM(INDIRECT("CE"&ROW(CE18) - $BI$4&":CE" & ROW(CE17)))=$BI$4,$CM17<>""),"Sim","") | CQ17: =IF(AND(SUM(INDIRECT("CF"&ROW(CF18) - $BI$4&":CF" & ROW(CF17)))=$BI$4,$CM17<>""),"Sim","") | CR17: =IF(AND(SUM(INDIRECT("CG"&ROW(CG18) - $BI$4&":CG" & ROW(CG17)))=$BI$4,$CM17<>""),"Sim","") | CS17: =IF(AND(SUM(INDIRECT("CH"&ROW(CH18) - $BI$4&":CH" & ROW(CH17)))=$BI$4,$CM17<>""),"Sim","") | CT17: =IF(AND(SUM(INDIRECT("CI"&ROW(CI18) - $BI$4&":CI" & ROW(CI17)))=$BI$4,$CM17<>""),"Sim","") | CU17: =IF(AND(SUM(INDIRECT("CJ"&ROW(CJ18) - $BI$4&":CJ" & ROW(CJ17)))=$BI$4,$CM17<>""),"Sim","") | CV17: =IF(AND(SUM(INDIRECT("CK"&ROW(CK18) - $BI$4&":CK" & ROW(CK17)))=$BI$4,$CM17<>""),"Sim","") | CW17: =IF(AND(SUM(INDIRECT("CL"&ROW(CL18) - $BI$4&":CL" & ROW(CL17)))=$BI$4,$CM17<>""),"Sim","") | DB17: =IF(DD17<>"","Mai.","") | DC17: 5 | DD17: =IFERROR(__xludf.DUMMYFUNCTION("IFERROR(AVERAGE(FILTER(INDIRECT(ADDRESS(13, (MATCH($BB$4, $12:$12, 0))) & "":"" & ADDRESS(1000, (MATCH($BB$4, $12:$12, 0)))), $DW$13:$DW$500 = DC17,$A$13:$A$500 >= $DQ$25,$A$13:$A$500 <= $DQ$26)),"""") "),"") | DF17: =$N$10 -> Esperar | DG17: =IFERROR(__xludf.DUMMYFUNCTION("IFERROR(AVERAGE(FILTER(INDIRECT(ADDRESS(13,(MATCH(DF17,$12:$12,0))) & "":"" & ADDRESS(1000, (MATCH(DF17,$12:$12,0)))),$A$13:$A$500 >= $DQ$25,$A$13:$A$500 <= $DQ$26)),"""")"),1.0) -> 1 | DI17: =IF(DK17=1,$N$10,"") -> Esperar | DJ17: =IF(INDEX($CN$10:$CW$12,1,ROW(BV4))="Recurso Adquirido",INDEX($CN$10:$CW$12,1,ROW(BV4)),"") -> Recurso Adquirido | DK17: =IF(DJ17="Recurso Adquirido",1,"") -> 1 | DM17: =$N$10 -> Esperar | DN17: =IFERROR(__xludf.DUMMYFUNCTION("IFERROR(AVERAGE(FILTER(INDIRECT(ADDRESS(13, (MATCH(DM17, $12:$12, 0))) & "":"" & ADDRESS(1000, (MATCH(DM17, $12:$12, 0)))), $A$13:$A$500 > (DATE(YEAR((TODAY()-(30*2))),MONTH((TODAY()-(30*2))),1)))),"""") "),"") | DQ17: =DATE(DP17,1,1) -> 2 | DU17: =A17 | DV17: =ABA!$A17 | DW17: =IF(DV17<>"",MONTH(DV17),"")
AP18: =IFERROR(AVERAGE(CC18,CD18,CE18,CF18,CG18,CH18,CI18,CJ18,CK18,CL18),"") | CB18: =A18 | CC18: =IFERROR(((B18*(IF(B$11="",INDEX($P$3:$Q$6,MATCH($B$12,$P$3:$P$6,0),2),B$11)))+(C18*(IF(C$11="",INDEX($P$3:$Q$6,MATCH($C$12,$P$3:$P$6,0),2),C$11)))+(D18*IF(D$11="",INDEX($P$3:$Q$6,MATCH($D$12,$P$3:$P$6,0),2),D$11))+(E18*IF(E$11="",INDEX($P$3:$Q$6,MATCH($E$12,$P$3:$P$6,0),2),E$11)))/SUM(B18:E18),"") | CD18: =IFERROR(((F18*(IF(F$11="",INDEX($P$3:$Q$6,MATCH($B$12,$P$3:$P$6,0),2),F$11)))+(G18*(IF(G$11="",INDEX($P$3:$Q$6,MATCH($C$12,$P$3:$P$6,0),2),G$11)))+(H18*IF(H$11="",INDEX($P$3:$Q$6,MATCH($D$12,$P$3:$P$6,0),2),H$11))+(I18*IF(I$11="",INDEX($P$3:$Q$6,MATCH($E$12,$P$3:$P$6,0),2),I$11)))/SUM(F18:I18),"") | CE18: =IFERROR(((J18*(IF(J$11="",INDEX($P$3:$Q$6,MATCH($B$12,$P$3:$P$6,0),2),J$11)))+(K18*(IF(K$11="",INDEX($P$3:$Q$6,MATCH($C$12,$P$3:$P$6,0),2),K$11)))+(L18*IF(L$11="",INDEX($P$3:$Q$6,MATCH($D$12,$P$3:$P$6,0),2),L$11))+(M18*IF(M$11="",INDEX($P$3:$Q$6,MATCH($E$12,$P$3:$P$6,0),2),M$11)))/SUM(J18:M18),"") | CF18: =IFERROR(((N18*(IF(N$11="",INDEX($P$3:$Q$6,MATCH($B$12,$P$3:$P$6,0),2),N$11)))+(O18*(IF(O$11="",INDEX($P$3:$Q$6,MATCH($C$12,$P$3:$P$6,0),2),O$11)))+(P18*IF(P$11="",INDEX($P$3:$Q$6,MATCH($D$12,$P$3:$P$6,0),2),P$11))+(Q18*IF(Q$11="",INDEX($P$3:$Q$6,MATCH($E$12,$P$3:$P$6,0),2),Q$11)))/SUM(N18:Q18),"") | CG18: =IFERROR(((R18*(IF(R$11="",INDEX($P$3:$Q$6,MATCH($B$12,$P$3:$P$6,0),2),R$11)))+(S18*(IF(S$11="",INDEX($P$3:$Q$6,MATCH($C$12,$P$3:$P$6,0),2),S$11)))+(T18*IF(T$11="",INDEX($P$3:$Q$6,MATCH($D$12,$P$3:$P$6,0),2),T$11))+(U18*IF(U$11="",INDEX($P$3:$Q$6,MATCH($E$12,$P$3:$P$6,0),2),U$11)))/SUM(R18:U18),"") | CH18: =IFERROR(((V18*(IF(V$11="",INDEX($P$3:$Q$6,MATCH($B$12,$P$3:$P$6,0),2),V$11)))+(W18*(IF(W$11="",INDEX($P$3:$Q$6,MATCH($C$12,$P$3:$P$6,0),2),W$11)))+(X18*IF(X$11="",INDEX($P$3:$Q$6,MATCH($D$12,$P$3:$P$6,0),2),X$11))+(Y18*IF(Y$11="",INDEX($P$3:$Q$6,MATCH($E$12,$P$3:$P$6,0),2),Y$11)))/SUM(V18:Y18),"") | CI18: =IFERROR(((Z18*(IF(Z$11="",INDEX($P$3:$Q$6,MATCH($B$12,$P$3:$P$6,0),2),Z$11)))+(AA18*(IF(AA$11="",INDEX($P$3:$Q$6,MATCH($C$12,$P$3:$P$6,0),2),AA$11)))+(AB18*IF(AB$11="",INDEX($P$3:$Q$6,MATCH($D$12,$P$3:$P$6,0),2),AB$11))+(AC18*IF(AC$11="",INDEX($P$3:$Q$6,MATCH($E$12,$P$3:$P$6,0),2),AC$11)))/SUM(Z18:AC18),"") | CJ18: =IFERROR(((AD18*(IF(AD$11="",INDEX($P$3:$Q$6,MATCH($B$12,$P$3:$P$6,0),2),AD$11)))+(AE18*(IF(AE$11="",INDEX($P$3:$Q$6,MATCH($C$12,$P$3:$P$6,0),2),AE$11)))+(AF18*IF(AF$11="",INDEX($P$3:$Q$6,MATCH($D$12,$P$3:$P$6,0),2),AF$11))+(AG18*IF(AG$11="",INDEX($P$3:$Q$6,MATCH($E$12,$P$3:$P$6,0),2),L$11)))/SUM(AD18:AG18),"") | CK18: =IFERROR(((AH18*(IF(AH$11="",INDEX($P$3:$Q$6,MATCH($B$12,$P$3:$P$6,0),2),AH$11)))+(AI18*(IF(AI$11="",INDEX($P$3:$Q$6,MATCH($C$12,$P$3:$P$6,0),2),AI$11)))+(AJ18*IF(AJ$11="",INDEX($P$3:$Q$6,MATCH($D$12,$P$3:$P$6,0),2),AJ$11))+(AK18*IF(AK$11="",INDEX($P$3:$Q$6,MATCH($E$12,$P$3:$P$6,0),2),AK$11)))/SUM(AH18:AK18),"") | CL18: =IFERROR(((AL18*(IF(AL$11="",INDEX($P$3:$Q$6,MATCH($B$12,$P$3:$P$6,0),2),AL$11)))+(AM18*(IF(AM$11="",INDEX($P$3:$Q$6,MATCH($C$12,$P$3:$P$6,0),2),AM$11)))+(AN18*IF(AN$11="",INDEX($P$3:$Q$6,MATCH($D$12,$P$3:$P$6,0),2),AN$11))+(AO18*IF(AO$11="",INDEX($P$3:$Q$6,MATCH($E$12,$P$3:$P$6,0),2),AO$11)))/SUM(AL18:AO18),"") | CM18: =A18 | CN18: =IF(AND(SUM(INDIRECT("CC"&ROW(CC19) - $BI$4&":CC" & ROW(CC18)))=$BI$4,CM18<>""),"Sim","") | CO18: =IF(AND(SUM(INDIRECT("CD"&ROW(CD19) - $BI$4&":CD" & ROW(CD18)))=$BI$4,$CM18<>""),"Sim","") | CP18: =IF(AND(SUM(INDIRECT("CE"&ROW(CE19) - $BI$4&":CE" & ROW(CE18)))=$BI$4,$CM18<>""),"Sim","") | CQ18: =IF(AND(SUM(INDIRECT("CF"&ROW(CF19) - $BI$4&":CF" & ROW(CF18)))=$BI$4,$CM18<>""),"Sim","") | CR18: =IF(AND(SUM(INDIRECT("CG"&ROW(CG19) - $BI$4&":CG" & ROW(CG18)))=$BI$4,$CM18<>""),"Sim","") | CS18: =IF(AND(SUM(INDIRECT("CH"&ROW(CH19) - $BI$4&":CH" & ROW(CH18)))=$BI$4,$CM18<>""),"Sim","") | CT18: =IF(AND(SUM(INDIRECT("CI"&ROW(CI19) - $BI$4&":CI" & ROW(CI18)))=$BI$4,$CM18<>""),"Sim","") | CU18: =IF(AND(SUM(INDIRECT("CJ"&ROW(CJ19) - $BI$4&":CJ" & ROW(CJ18)))=$BI$4,$CM18<>""),"Sim","") | CV18: =IF(AND(SUM(INDIRECT("CK"&ROW(CK19) - $BI$4&":CK" & ROW(CK18)))=$BI$4,$CM18<>""),"Sim","") | CW18: =IF(AND(SUM(INDIRECT("CL"&ROW(CL19) - $BI$4&":CL" & ROW(CL18)))=$BI$4,$CM18<>""),"Sim","") | DB18: =IF(DD18<>"","Jun.","") | DC18: 6 | DD18: =IFERROR(__xludf.DUMMYFUNCTION("IFERROR(AVERAGE(FILTER(INDIRECT(ADDRESS(13, (MATCH($BB$4, $12:$12, 0))) & "":"" & ADDRESS(1000, (MATCH($BB$4, $12:$12, 0)))), $DW$13:$DW$500 = DC18,$A$13:$A$500 >= $DQ$25,$A$13:$A$500 <= $DQ$26)),"""") "),"") | DF18: =$R$10 -> Seguir instruções de um passo | DG18: =IFERROR(__xludf.DUMMYFUNCTION("IFERROR(AVERAGE(FILTER(INDIRECT(ADDRESS(13,(MATCH(DF18,$12:$12,0))) & "":"" & ADDRESS(1000, (MATCH(DF18,$12:$12,0)))),$A$13:$A$500 >= $DQ$25,$A$13:$A$500 <= $DQ$26)),"""")"),1.0) -> 1 | DI18: =IF(DK18=1,$R$10,"") -> Seguir instruções de um passo | DJ18: =IF(INDEX($CN$10:$CW$12,1,ROW(BV5))="Recurso Adquirido",INDEX($CN$10:$CW$12,1,ROW(BV5)),"") -> Recurso Adquirido | DK18: =IF(DJ18="Recurso Adquirido",1,"") -> 1 | DM18: =$R$10 -> Seguir instruções de um passo | DN18: =IFERROR(__xludf.DUMMYFUNCTION("IFERROR(AVERAGE(FILTER(INDIRECT(ADDRESS(13, (MATCH(DM18, $12:$12, 0))) & "":"" & ADDRESS(1000, (MATCH(DM18, $12:$12, 0)))), $A$13:$A$500 > (DATE(YEAR((TODAY()-(30*2))),MONTH((TODAY()-(30*2))),1)))),"""") "),"") | DQ18: =DATE(DP18,1,1) -> 2 | DU18: =A18 | DV18: =ABA!$A18 | DW18: =IF(DV18<>"",MONTH(DV18),"")
AP19: =IFERROR(AVERAGE(CC19,CD19,CE19,CF19,CG19,CH19,CI19,CJ19,CK19,CL19),"") | CB19: =A19 | CC19: =IFERROR(((B19*(IF(B$11="",INDEX($P$3:$Q$6,MATCH($B$12,$P$3:$P$6,0),2),B$11)))+(C19*(IF(C$11="",INDEX($P$3:$Q$6,MATCH($C$12,$P$3:$P$6,0),2),C$11)))+(D19*IF(D$11="",INDEX($P$3:$Q$6,MATCH($D$12,$P$3:$P$6,0),2),D$11))+(E19*IF(E$11="",INDEX($P$3:$Q$6,MATCH($E$12,$P$3:$P$6,0),2),E$11)))/SUM(B19:E19),"") | CD19: =IFERROR(((F19*(IF(F$11="",INDEX($P$3:$Q$6,MATCH($B$12,$P$3:$P$6,0),2),F$11)))+(G19*(IF(G$11="",INDEX($P$3:$Q$6,MATCH($C$12,$P$3:$P$6,0),2),G$11)))+(H19*IF(H$11="",INDEX($P$3:$Q$6,MATCH($D$12,$P$3:$P$6,0),2),H$11))+(I19*IF(I$11="",INDEX($P$3:$Q$6,MATCH($E$12,$P$3:$P$6,0),2),I$11)))/SUM(F19:I19),"") | CE19: =IFERROR(((J19*(IF(J$11="",INDEX($P$3:$Q$6,MATCH($B$12,$P$3:$P$6,0),2),J$11)))+(K19*(IF(K$11="",INDEX($P$3:$Q$6,MATCH($C$12,$P$3:$P$6,0),2),K$11)))+(L19*IF(L$11="",INDEX($P$3:$Q$6,MATCH($D$12,$P$3:$P$6,0),2),L$11))+(M19*IF(M$11="",INDEX($P$3:$Q$6,MATCH($E$12,$P$3:$P$6,0),2),M$11)))/SUM(J19:M19),"") | CF19: =IFERROR(((N19*(IF(N$11="",INDEX($P$3:$Q$6,MATCH($B$12,$P$3:$P$6,0),2),N$11)))+(O19*(IF(O$11="",INDEX($P$3:$Q$6,MATCH($C$12,$P$3:$P$6,0),2),O$11)))+(P19*IF(P$11="",INDEX($P$3:$Q$6,MATCH($D$12,$P$3:$P$6,0),2),P$11))+(Q19*IF(Q$11="",INDEX($P$3:$Q$6,MATCH($E$12,$P$3:$P$6,0),2),Q$11)))/SUM(N19:Q19),"") | CG19: =IFERROR(((R19*(IF(R$11="",INDEX($P$3:$Q$6,MATCH($B$12,$P$3:$P$6,0),2),R$11)))+(S19*(IF(S$11="",INDEX($P$3:$Q$6,MATCH($C$12,$P$3:$P$6,0),2),S$11)))+(T19*IF(T$11="",INDEX($P$3:$Q$6,MATCH($D$12,$P$3:$P$6,0),2),T$11))+(U19*IF(U$11="",INDEX($P$3:$Q$6,MATCH($E$12,$P$3:$P$6,0),2),U$11)))/SUM(R19:U19),"") | CH19: =IFERROR(((V19*(IF(V$11="",INDEX($P$3:$Q$6,MATCH($B$12,$P$3:$P$6,0),2),V$11)))+(W19*(IF(W$11="",INDEX($P$3:$Q$6,MATCH($C$12,$P$3:$P$6,0),2),W$11)))+(X19*IF(X$11="",INDEX($P$3:$Q$6,MATCH($D$12,$P$3:$P$6,0),2),X$11))+(Y19*IF(Y$11="",INDEX($P$3:$Q$6,MATCH($E$12,$P$3:$P$6,0),2),Y$11)))/SUM(V19:Y19),"") | CI19: =IFERROR(((Z19*(IF(Z$11="",INDEX($P$3:$Q$6,MATCH($B$12,$P$3:$P$6,0),2),Z$11)))+(AA19*(IF(AA$11="",INDEX($P$3:$Q$6,MATCH($C$12,$P$3:$P$6,0),2),AA$11)))+(AB19*IF(AB$11="",INDEX($P$3:$Q$6,MATCH($D$12,$P$3:$P$6,0),2),AB$11))+(AC19*IF(AC$11="",INDEX($P$3:$Q$6,MATCH($E$12,$P$3:$P$6,0),2),AC$11)))/SUM(Z19:AC19),"") | CJ19: =IFERROR(((AD19*(IF(AD$11="",INDEX($P$3:$Q$6,MATCH($B$12,$P$3:$P$6,0),2),AD$11)))+(AE19*(IF(AE$11="",INDEX($P$3:$Q$6,MATCH($C$12,$P$3:$P$6,0),2),AE$11)))+(AF19*IF(AF$11="",INDEX($P$3:$Q$6,MATCH($D$12,$P$3:$P$6,0),2),AF$11))+(AG19*IF(AG$11="",INDEX($P$3:$Q$6,MATCH($E$12,$P$3:$P$6,0),2),L$11)))/SUM(AD19:AG19),"") | CK19: =IFERROR(((AH19*(IF(AH$11="",INDEX($P$3:$Q$6,MATCH($B$12,$P$3:$P$6,0),2),AH$11)))+(AI19*(IF(AI$11="",INDEX($P$3:$Q$6,MATCH($C$12,$P$3:$P$6,0),2),AI$11)))+(AJ19*IF(AJ$11="",INDEX($P$3:$Q$6,MATCH($D$12,$P$3:$P$6,0),2),AJ$11))+(AK19*IF(AK$11="",INDEX($P$3:$Q$6,MATCH($E$12,$P$3:$P$6,0),2),AK$11)))/SUM(AH19:AK19),"") | CL19: =IFERROR(((AL19*(IF(AL$11="",INDEX($P$3:$Q$6,MATCH($B$12,$P$3:$P$6,0),2),AL$11)))+(AM19*(IF(AM$11="",INDEX($P$3:$Q$6,MATCH($C$12,$P$3:$P$6,0),2),AM$11)))+(AN19*IF(AN$11="",INDEX($P$3:$Q$6,MATCH($D$12,$P$3:$P$6,0),2),AN$11))+(AO19*IF(AO$11="",INDEX($P$3:$Q$6,MATCH($E$12,$P$3:$P$6,0),2),AO$11)))/SUM(AL19:AO19),"") | CM19: =A19 | CN19: =IF(AND(SUM(INDIRECT("CC"&ROW(CC20) - $BI$4&":CC" & ROW(CC19)))=$BI$4,CM19<>""),"Sim","") | CO19: =IF(AND(SUM(INDIRECT("CD"&ROW(CD20) - $BI$4&":CD" & ROW(CD19)))=$BI$4,$CM19<>""),"Sim","") | CP19: =IF(AND(SUM(INDIRECT("CE"&ROW(CE20) - $BI$4&":CE" & ROW(CE19)))=$BI$4,$CM19<>""),"Sim","") | CQ19: =IF(AND(SUM(INDIRECT("CF"&ROW(CF20) - $BI$4&":CF" & ROW(CF19)))=$BI$4,$CM19<>""),"Sim","") | CR19: =IF(AND(SUM(INDIRECT("CG"&ROW(CG20) - $BI$4&":CG" & ROW(CG19)))=$BI$4,$CM19<>""),"Sim","") | CS19: =IF(AND(SUM(INDIRECT("CH"&ROW(CH20) - $BI$4&":CH" & ROW(CH19)))=$BI$4,$CM19<>""),"Sim","") | CT19: =IF(AND(SUM(INDIRECT("CI"&ROW(CI20) - $BI$4&":CI" & ROW(CI19)))=$BI$4,$CM19<>""),"Sim","") | CU19: =IF(AND(SUM(INDIRECT("CJ"&ROW(CJ20) - $BI$4&":CJ" & ROW(CJ19)))=$BI$4,$CM19<>""),"Sim","") | CV19: =IF(AND(SUM(INDIRECT("CK"&ROW(CK20) - $BI$4&":CK" & ROW(CK19)))=$BI$4,$CM19<>""),"Sim","") | CW19: =IF(AND(SUM(INDIRECT("CL"&ROW(CL20) - $BI$4&":CL" & ROW(CL19)))=$BI$4,$CM19<>""),"Sim","") | DB19: =IF(DD19<>"","Jul.","") | DC19: 7 | DD19: =IFERROR(__xludf.DUMMYFUNCTION("IFERROR(AVERAGE(FILTER(INDIRECT(ADDRESS(13, (MATCH($BB$4, $12:$12, 0))) & "":"" & ADDRESS(1000, (MATCH($BB$4, $12:$12, 0)))), $DW$13:$DW$500 = DC19,$A$13:$A$500 >= $DQ$25,$A$13:$A$500 <= $DQ$26)),"""") "),"") | DF19: =$V$10 | DG19: =IFERROR(__xludf.DUMMYFUNCTION("IFERROR(AVERAGE(FILTER(INDIRECT(ADDRESS(13,(MATCH(DF19,$12:$12,0))) & "":"" & ADDRESS(1000, (MATCH(DF19,$12:$12,0)))),$A$13:$A$500 >= $DQ$25,$A$13:$A$500 <= $DQ$26)),"""")"),"") | DI19: =IF(DK19=1,$V$10,"") | DJ19: =IF(INDEX($CN$10:$CW$12,1,ROW(BV6))="Recurso Adquirido",INDEX($CN$10:$CW$12,1,ROW(BV6)),"") | DK19: =IF(DJ19="Recurso Adquirido",1,"") | DM19: =$V$10 | DN19: =IFERROR(__xludf.DUMMYFUNCTION("IFERROR(AVERAGE(FILTER(INDIRECT(ADDRESS(13, (MATCH(DM19, $12:$12, 0))) & "":"" & ADDRESS(1000, (MATCH(DM19, $12:$12, 0)))), $A$13:$A$500 > (DATE(YEAR((TODAY()-(30*2))),MONTH((TODAY()-(30*2))),1)))),"""") "),"") | DQ19: =DATE(DP19,1,1) -> 2 | DU19: =A19 | DV19: =ABA!$A19 | DW19: =IF(DV19<>"",MONTH(DV19),"")
AP20: =IFERROR(AVERAGE(CC20,CD20,CE20,CF20,CG20,CH20,CI20,CJ20,CK20,CL20),"") | CB20: =A20 | CC20: =IFERROR(((B20*(IF(B$11="",INDEX($P$3:$Q$6,MATCH($B$12,$P$3:$P$6,0),2),B$11)))+(C20*(IF(C$11="",INDEX($P$3:$Q$6,MATCH($C$12,$P$3:$P$6,0),2),C$11)))+(D20*IF(D$11="",INDEX($P$3:$Q$6,MATCH($D$12,$P$3:$P$6,0),2),D$11))+(E20*IF(E$11="",INDEX($P$3:$Q$6,MATCH($E$12,$P$3:$P$6,0),2),E$11)))/SUM(B20:E20),"") | CD20: =IFERROR(((F20*(IF(F$11="",INDEX($P$3:$Q$6,MATCH($B$12,$P$3:$P$6,0),2),F$11)))+(G20*(IF(G$11="",INDEX($P$3:$Q$6,MATCH($C$12,$P$3:$P$6,0),2),G$11)))+(H20*IF(H$11="",INDEX($P$3:$Q$6,MATCH($D$12,$P$3:$P$6,0),2),H$11))+(I20*IF(I$11="",INDEX($P$3:$Q$6,MATCH($E$12,$P$3:$P$6,0),2),I$11)))/SUM(F20:I20),"") | CE20: =IFERROR(((J20*(IF(J$11="",INDEX($P$3:$Q$6,MATCH($B$12,$P$3:$P$6,0),2),J$11)))+(K20*(IF(K$11="",INDEX($P$3:$Q$6,MATCH($C$12,$P$3:$P$6,0),2),K$11)))+(L20*IF(L$11="",INDEX($P$3:$Q$6,MATCH($D$12,$P$3:$P$6,0),2),L$11))+(M20*IF(M$11="",INDEX($P$3:$Q$6,MATCH($E$12,$P$3:$P$6,0),2),M$11)))/SUM(J20:M20),"") | CF20: =IFERROR(((N20*(IF(N$11="",INDEX($P$3:$Q$6,MATCH($B$12,$P$3:$P$6,0),2),N$11)))+(O20*(IF(O$11="",INDEX($P$3:$Q$6,MATCH($C$12,$P$3:$P$6,0),2),O$11)))+(P20*IF(P$11="",INDEX($P$3:$Q$6,MATCH($D$12,$P$3:$P$6,0),2),P$11))+(Q20*IF(Q$11="",INDEX($P$3:$Q$6,MATCH($E$12,$P$3:$P$6,0),2),Q$11)))/SUM(N20:Q20),"") | CG20: =IFERROR(((R20*(IF(R$11="",INDEX($P$3:$Q$6,MATCH($B$12,$P$3:$P$6,0),2),R$11)))+(S20*(IF(S$11="",INDEX($P$3:$Q$6,MATCH($C$12,$P$3:$P$6,0),2),S$11)))+(T20*IF(T$11="",INDEX($P$3:$Q$6,MATCH($D$12,$P$3:$P$6,0),2),T$11))+(U20*IF(U$11="",INDEX($P$3:$Q$6,MATCH($E$12,$P$3:$P$6,0),2),U$11)))/SUM(R20:U20),"") | CH20: =IFERROR(((V20*(IF(V$11="",INDEX($P$3:$Q$6,MATCH($B$12,$P$3:$P$6,0),2),V$11)))+(W20*(IF(W$11="",INDEX($P$3:$Q$6,MATCH($C$12,$P$3:$P$6,0),2),W$11)))+(X20*IF(X$11="",INDEX($P$3:$Q$6,MATCH($D$12,$P$3:$P$6,0),2),X$11))+(Y20*IF(Y$11="",INDEX($P$3:$Q$6,MATCH($E$12,$P$3:$P$6,0),2),Y$11)))/SUM(V20:Y20),"") | CI20: =IFERROR(((Z20*(IF(Z$11="",INDEX($P$3:$Q$6,MATCH($B$12,$P$3:$P$6,0),2),Z$11)))+(AA20*(IF(AA$11="",INDEX($P$3:$Q$6,MATCH($C$12,$P$3:$P$6,0),2),AA$11)))+(AB20*IF(AB$11="",INDEX($P$3:$Q$6,MATCH($D$12,$P$3:$P$6,0),2),AB$11))+(AC20*IF(AC$11="",INDEX($P$3:$Q$6,MATCH($E$12,$P$3:$P$6,0),2),AC$11)))/SUM(Z20:AC20),"") | CJ20: =IFERROR(((AD20*(IF(AD$11="",INDEX($P$3:$Q$6,MATCH($B$12,$P$3:$P$6,0),2),AD$11)))+(AE20*(IF(AE$11="",INDEX($P$3:$Q$6,MATCH($C$12,$P$3:$P$6,0),2),AE$11)))+(AF20*IF(AF$11="",INDEX($P$3:$Q$6,MATCH($D$12,$P$3:$P$6,0),2),AF$11))+(AG20*IF(AG$11="",INDEX($P$3:$Q$6,MATCH($E$12,$P$3:$P$6,0),2),L$11)))/SUM(AD20:AG20),"") | CK20: =IFERROR(((AH20*(IF(AH$11="",INDEX($P$3:$Q$6,MATCH($B$12,$P$3:$P$6,0),2),AH$11)))+(AI20*(IF(AI$11="",INDEX($P$3:$Q$6,MATCH($C$12,$P$3:$P$6,0),2),AI$11)))+(AJ20*IF(AJ$11="",INDEX($P$3:$Q$6,MATCH($D$12,$P$3:$P$6,0),2),AJ$11))+(AK20*IF(AK$11="",INDEX($P$3:$Q$6,MATCH($E$12,$P$3:$P$6,0),2),AK$11)))/SUM(AH20:AK20),"") | CL20: =IFERROR(((AL20*(IF(AL$11="",INDEX($P$3:$Q$6,MATCH($B$12,$P$3:$P$6,0),2),AL$11)))+(AM20*(IF(AM$11="",INDEX($P$3:$Q$6,MATCH($C$12,$P$3:$P$6,0),2),AM$11)))+(AN20*IF(AN$11="",INDEX($P$3:$Q$6,MATCH($D$12,$P$3:$P$6,0),2),AN$11))+(AO20*IF(AO$11="",INDEX($P$3:$Q$6,MATCH($E$12,$P$3:$P$6,0),2),AO$11)))/SUM(AL20:AO20),"") | CM20: =A20 | CN20: =IF(AND(SUM(INDIRECT("CC"&ROW(CC21) - $BI$4&":CC" & ROW(CC20)))=$BI$4,CM20<>""),"Sim","") | CO20: =IF(AND(SUM(INDIRECT("CD"&ROW(CD21) - $BI$4&":CD" & ROW(CD20)))=$BI$4,$CM20<>""),"Sim","") | CP20: =IF(AND(SUM(INDIRECT("CE"&ROW(CE21) - $BI$4&":CE" & ROW(CE20)))=$BI$4,$CM20<>""),"Sim","") | CQ20: =IF(AND(SUM(INDIRECT("CF"&ROW(CF21) - $BI$4&":CF" & ROW(CF20)))=$BI$4,$CM20<>""),"Sim","") | CR20: =IF(AND(SUM(INDIRECT("CG"&ROW(CG21) - $BI$4&":CG" & ROW(CG20)))=$BI$4,$CM20<>""),"Sim","") | CS20: =IF(AND(SUM(INDIRECT("CH"&ROW(CH21) - $BI$4&":CH" & ROW(CH20)))=$BI$4,$CM20<>""),"Sim","") | CT20: =IF(AND(SUM(INDIRECT("CI"&ROW(CI21) - $BI$4&":CI" & ROW(CI20)))=$BI$4,$CM20<>""),"Sim","") | CU20: =IF(AND(SUM(INDIRECT("CJ"&ROW(CJ21) - $BI$4&":CJ" & ROW(CJ20)))=$BI$4,$CM20<>""),"Sim","") | CV20: =IF(AND(SUM(INDIRECT("CK"&ROW(CK21) - $BI$4&":CK" & ROW(CK20)))=$BI$4,$CM20<>""),"Sim","") | CW20: =IF(AND(SUM(INDIRECT("CL"&ROW(CL21) - $BI$4&":CL" & ROW(CL20)))=$BI$4,$CM20<>""),"Sim","") | DB20: =IF(DD20<>"","Ago.","") | DC20: 8 | DD20: =IFERROR(__xludf.DUMMYFUNCTION("IFERROR(AVERAGE(FILTER(INDIRECT(ADDRESS(13, (MATCH($BB$4, $12:$12, 0))) & "":"" & ADDRESS(1000, (MATCH($BB$4, $12:$12, 0)))), $DW$13:$DW$500 = DC20,$A$13:$A$500 >= $DQ$25,$A$13:$A$500 <= $DQ$26)),"""") "),"") | DF20: =$Z$10 | DG20: =IFERROR(__xludf.DUMMYFUNCTION("IFERROR(AVERAGE(FILTER(INDIRECT(ADDRESS(13,(MATCH(DF20,$12:$12,0))) & "":"" & ADDRESS(1000, (MATCH(DF20,$12:$12,0)))),$A$13:$A$500 >= $DQ$25,$A$13:$A$500 <= $DQ$26)),"""")"),"") | DI20: =IF(DK20=1,$Z$10,"") | DJ20: =IF(INDEX($CN$10:$CW$12,1,ROW(BV7))="Recurso Adquirido",INDEX($CN$10:$CW$12,1,ROW(BV7)),"") | DK20: =IF(DJ20="Recurso Adquirido",1,"") | DM20: =$Z$10 | DN20: =IFERROR(__xludf.DUMMYFUNCTION("IFERROR(AVERAGE(FILTER(INDIRECT(ADDRESS(13, (MATCH(DM20, $12:$12, 0))) & "":"" & ADDRESS(1000, (MATCH(DM20, $12:$12, 0)))), $A$13:$A$500 > (DATE(YEAR((TODAY()-(30*2))),MONTH((TODAY()-(30*2))),1)))),"""") "),"") | DQ20: =DATE(DP20,1,1) -> 2 | DU20: =A20 | DV20: =ABA!$A20 | DW20: =IF(DV20<>"",MONTH(DV20),"")
AP21: =IFERROR(AVERAGE(CC21,CD21,CE21,CF21,CG21,CH21,CI21,CJ21,CK21,CL21),"") | CB21: =A21 | CC21: =IFERROR(((B21*(IF(B$11="",INDEX($P$3:$Q$6,MATCH($B$12,$P$3:$P$6,0),2),B$11)))+(C21*(IF(C$11="",INDEX($P$3:$Q$6,MATCH($C$12,$P$3:$P$6,0),2),C$11)))+(D21*IF(D$11="",INDEX($P$3:$Q$6,MATCH($D$12,$P$3:$P$6,0),2),D$11))+(E21*IF(E$11="",INDEX($P$3:$Q$6,MATCH($E$12,$P$3:$P$6,0),2),E$11)))/SUM(B21:E21),"") | CD21: =IFERROR(((F21*(IF(F$11="",INDEX($P$3:$Q$6,MATCH($B$12,$P$3:$P$6,0),2),F$11)))+(G21*(IF(G$11="",INDEX($P$3:$Q$6,MATCH($C$12,$P$3:$P$6,0),2),G$11)))+(H21*IF(H$11="",INDEX($P$3:$Q$6,MATCH($D$12,$P$3:$P$6,0),2),H$11))+(I21*IF(I$11="",INDEX($P$3:$Q$6,MATCH($E$12,$P$3:$P$6,0),2),I$11)))/SUM(F21:I21),"") | CE21: =IFERROR(((J21*(IF(J$11="",INDEX($P$3:$Q$6,MATCH($B$12,$P$3:$P$6,0),2),J$11)))+(K21*(IF(K$11="",INDEX($P$3:$Q$6,MATCH($C$12,$P$3:$P$6,0),2),K$11)))+(L21*IF(L$11="",INDEX($P$3:$Q$6,MATCH($D$12,$P$3:$P$6,0),2),L$11))+(M21*IF(M$11="",INDEX($P$3:$Q$6,MATCH($E$12,$P$3:$P$6,0),2),M$11)))/SUM(J21:M21),"") | CF21: =IFERROR(((N21*(IF(N$11="",INDEX($P$3:$Q$6,MATCH($B$12,$P$3:$P$6,0),2),N$11)))+(O21*(IF(O$11="",INDEX($P$3:$Q$6,MATCH($C$12,$P$3:$P$6,0),2),O$11)))+(P21*IF(P$11="",INDEX($P$3:$Q$6,MATCH($D$12,$P$3:$P$6,0),2),P$11))+(Q21*IF(Q$11="",INDEX($P$3:$Q$6,MATCH($E$12,$P$3:$P$6,0),2),Q$11)))/SUM(N21:Q21),"") | CG21: =IFERROR(((R21*(IF(R$11="",INDEX($P$3:$Q$6,MATCH($B$12,$P$3:$P$6,0),2),R$11)))+(S21*(IF(S$11="",INDEX($P$3:$Q$6,MATCH($C$12,$P$3:$P$6,0),2),S$11)))+(T21*IF(T$11="",INDEX($P$3:$Q$6,MATCH($D$12,$P$3:$P$6,0),2),T$11))+(U21*IF(U$11="",INDEX($P$3:$Q$6,MATCH($E$12,$P$3:$P$6,0),2),U$11)))/SUM(R21:U21),"") | CH21: =IFERROR(((V21*(IF(V$11="",INDEX($P$3:$Q$6,MATCH($B$12,$P$3:$P$6,0),2),V$11)))+(W21*(IF(W$11="",INDEX($P$3:$Q$6,MATCH($C$12,$P$3:$P$6,0),2),W$11)))+(X21*IF(X$11="",INDEX($P$3:$Q$6,MATCH($D$12,$P$3:$P$6,0),2),X$11))+(Y21*IF(Y$11="",INDEX($P$3:$Q$6,MATCH($E$12,$P$3:$P$6,0),2),Y$11)))/SUM(V21:Y21),"") | CI21: =IFERROR(((Z21*(IF(Z$11="",INDEX($P$3:$Q$6,MATCH($B$12,$P$3:$P$6,0),2),Z$11)))+(AA21*(IF(AA$11="",INDEX($P$3:$Q$6,MATCH($C$12,$P$3:$P$6,0),2),AA$11)))+(AB21*IF(AB$11="",INDEX($P$3:$Q$6,MATCH($D$12,$P$3:$P$6,0),2),AB$11))+(AC21*IF(AC$11="",INDEX($P$3:$Q$6,MATCH($E$12,$P$3:$P$6,0),2),AC$11)))/SUM(Z21:AC21),"") | CJ21: =IFERROR(((AD21*(IF(AD$11="",INDEX($P$3:$Q$6,MATCH($B$12,$P$3:$P$6,0),2),AD$11)))+(AE21*(IF(AE$11="",INDEX($P$3:$Q$6,MATCH($C$12,$P$3:$P$6,0),2),AE$11)))+(AF21*IF(AF$11="",INDEX($P$3:$Q$6,MATCH($D$12,$P$3:$P$6,0),2),AF$11))+(AG21*IF(AG$11="",INDEX($P$3:$Q$6,MATCH($E$12,$P$3:$P$6,0),2),L$11)))/SUM(AD21:AG21),"") | CK21: =IFERROR(((AH21*(IF(AH$11="",INDEX($P$3:$Q$6,MATCH($B$12,$P$3:$P$6,0),2),AH$11)))+(AI21*(IF(AI$11="",INDEX($P$3:$Q$6,MATCH($C$12,$P$3:$P$6,0),2),AI$11)))+(AJ21*IF(AJ$11="",INDEX($P$3:$Q$6,MATCH($D$12,$P$3:$P$6,0),2),AJ$11))+(AK21*IF(AK$11="",INDEX($P$3:$Q$6,MATCH($E$12,$P$3:$P$6,0),2),AK$11)))/SUM(AH21:AK21),"") | CL21: =IFERROR(((AL21*(IF(AL$11="",INDEX($P$3:$Q$6,MATCH($B$12,$P$3:$P$6,0),2),AL$11)))+(AM21*(IF(AM$11="",INDEX($P$3:$Q$6,MATCH($C$12,$P$3:$P$6,0),2),AM$11)))+(AN21*IF(AN$11="",INDEX($P$3:$Q$6,MATCH($D$12,$P$3:$P$6,0),2),AN$11))+(AO21*IF(AO$11="",INDEX($P$3:$Q$6,MATCH($E$12,$P$3:$P$6,0),2),AO$11)))/SUM(AL21:AO21),"") | CM21: =A21 | CN21: =IF(AND(SUM(INDIRECT("CC"&ROW(CC22) - $BI$4&":CC" & ROW(CC21)))=$BI$4,CM21<>""),"Sim","") | CO21: =IF(AND(SUM(INDIRECT("CD"&ROW(CD22) - $BI$4&":CD" & ROW(CD21)))=$BI$4,$CM21<>""),"Sim","") | CP21: =IF(AND(SUM(INDIRECT("CE"&ROW(CE22) - $BI$4&":CE" & ROW(CE21)))=$BI$4,$CM21<>""),"Sim","") | CQ21: =IF(AND(SUM(INDIRECT("CF"&ROW(CF22) - $BI$4&":CF" & ROW(CF21)))=$BI$4,$CM21<>""),"Sim","") | CR21: =IF(AND(SUM(INDIRECT("CG"&ROW(CG22) - $BI$4&":CG" & ROW(CG21)))=$BI$4,$CM21<>""),"Sim","") | CS21: =IF(AND(SUM(INDIRECT("CH"&ROW(CH22) - $BI$4&":CH" & ROW(CH21)))=$BI$4,$CM21<>""),"Sim","") | CT21: =IF(AND(SUM(INDIRECT("CI"&ROW(CI22) - $BI$4&":CI" & ROW(CI21)))=$BI$4,$CM21<>""),"Sim","") | CU21: =IF(AND(SUM(INDIRECT("CJ"&ROW(CJ22) - $BI$4&":CJ" & ROW(CJ21)))=$BI$4,$CM21<>""),"Sim","") | CV21: =IF(AND(SUM(INDIRECT("CK"&ROW(CK22) - $BI$4&":CK" & ROW(CK21)))=$BI$4,$CM21<>""),"Sim","") | CW21: =IF(AND(SUM(INDIRECT("CL"&ROW(CL22) - $BI$4&":CL" & ROW(CL21)))=$BI$4,$CM21<>""),"Sim","") | DB21: =IF(DD21<>"","Set.","") | DC21: 9 | DD21: =IFERROR(__xludf.DUMMYFUNCTION("IFERROR(AVERAGE(FILTER(INDIRECT(ADDRESS(13, (MATCH($BB$4, $12:$12, 0))) & "":"" & ADDRESS(1000, (MATCH($BB$4, $12:$12, 0)))), $DW$13:$DW$500 = DC21,$A$13:$A$500 >= $DQ$25,$A$13:$A$500 <= $DQ$26)),"""") "),"") | DF21: =$AD$10 | DG21: =IFERROR(__xludf.DUMMYFUNCTION("IFERROR(AVERAGE(FILTER(INDIRECT(ADDRESS(13,(MATCH(DF21,$12:$12,0))) & "":"" & ADDRESS(1000, (MATCH(DF21,$12:$12,0)))),$A$13:$A$500 >= $DQ$25,$A$13:$A$500 <= $DQ$26)),"""")"),"") | DI21: =IF(DK21=1,$AD$10,"") | DJ21: =IF(INDEX($CN$10:$CW$12,1,ROW(BV8))="Recurso Adquirido",INDEX($CN$10:$CW$12,1,ROW(BV8)),"") | DK21: =IF(DJ21="Recurso Adquirido",1,"") | DM21: =$AD$10 | DN21: =IFERROR(__xludf.DUMMYFUNCTION("IFERROR(AVERAGE(FILTER(INDIRECT(ADDRESS(13, (MATCH(DM21, $12:$12, 0))) & "":"" & ADDRESS(1000, (MATCH(DM21, $12:$12, 0)))), $A$13:$A$500 > (DATE(YEAR((TODAY()-(30*2))),MONTH((TODAY()-(30*2))),1)))),"""") "),"") | DQ21: =DATE(DP21,1,1) -> 2 | DU21: =A21 | DV21: =ABA!$A21 | DW21: =IF(DV21<>"",MONTH(DV21),"")
AP22: =IFERROR(AVERAGE(CC22,CD22,CE22,CF22,CG22,CH22,CI22,CJ22,CK22,CL22),"") | CB22: =A22 | CC22: =IFERROR(((B22*(IF(B$11="",INDEX($P$3:$Q$6,MATCH($B$12,$P$3:$P$6,0),2),B$11)))+(C22*(IF(C$11="",INDEX($P$3:$Q$6,MATCH($C$12,$P$3:$P$6,0),2),C$11)))+(D22*IF(D$11="",INDEX($P$3:$Q$6,MATCH($D$12,$P$3:$P$6,0),2),D$11))+(E22*IF(E$11="",INDEX($P$3:$Q$6,MATCH($E$12,$P$3:$P$6,0),2),E$11)))/SUM(B22:E22),"") | CD22: =IFERROR(((F22*(IF(F$11="",INDEX($P$3:$Q$6,MATCH($B$12,$P$3:$P$6,0),2),F$11)))+(G22*(IF(G$11="",INDEX($P$3:$Q$6,MATCH($C$12,$P$3:$P$6,0),2),G$11)))+(H22*IF(H$11="",INDEX($P$3:$Q$6,MATCH($D$12,$P$3:$P$6,0),2),H$11))+(I22*IF(I$11="",INDEX($P$3:$Q$6,MATCH($E$12,$P$3:$P$6,0),2),I$11)))/SUM(F22:I22),"") | CE22: =IFERROR(((J22*(IF(J$11="",INDEX($P$3:$Q$6,MATCH($B$12,$P$3:$P$6,0),2),J$11)))+(K22*(IF(K$11="",INDEX($P$3:$Q$6,MATCH($C$12,$P$3:$P$6,0),2),K$11)))+(L22*IF(L$11="",INDEX($P$3:$Q$6,MATCH($D$12,$P$3:$P$6,0),2),L$11))+(M22*IF(M$11="",INDEX($P$3:$Q$6,MATCH($E$12,$P$3:$P$6,0),2),M$11)))/SUM(J22:M22),"") | CF22: =IFERROR(((N22*(IF(N$11="",INDEX($P$3:$Q$6,MATCH($B$12,$P$3:$P$6,0),2),N$11)))+(O22*(IF(O$11="",INDEX($P$3:$Q$6,MATCH($C$12,$P$3:$P$6,0),2),O$11)))+(P22*IF(P$11="",INDEX($P$3:$Q$6,MATCH($D$12,$P$3:$P$6,0),2),P$11))+(Q22*IF(Q$11="",INDEX($P$3:$Q$6,MATCH($E$12,$P$3:$P$6,0),2),Q$11)))/SUM(N22:Q22),"") | CG22: =IFERROR(((R22*(IF(R$11="",INDEX($P$3:$Q$6,MATCH($B$12,$P$3:$P$6,0),2),R$11)))+(S22*(IF(S$11="",INDEX($P$3:$Q$6,MATCH($C$12,$P$3:$P$6,0),2),S$11)))+(T22*IF(T$11="",INDEX($P$3:$Q$6,MATCH($D$12,$P$3:$P$6,0),2),T$11))+(U22*IF(U$11="",INDEX($P$3:$Q$6,MATCH($E$12,$P$3:$P$6,0),2),U$11)))/SUM(R22:U22),"") | CH22: =IFERROR(((V22*(IF(V$11="",INDEX($P$3:$Q$6,MATCH($B$12,$P$3:$P$6,0),2),V$11)))+(W22*(IF(W$11="",INDEX($P$3:$Q$6,MATCH($C$12,$P$3:$P$6,0),2),W$11)))+(X22*IF(X$11="",INDEX($P$3:$Q$6,MATCH($D$12,$P$3:$P$6,0),2),X$11))+(Y22*IF(Y$11="",INDEX($P$3:$Q$6,MATCH($E$12,$P$3:$P$6,0),2),Y$11)))/SUM(V22:Y22),"") | CI22: =IFERROR(((Z22*(IF(Z$11="",INDEX($P$3:$Q$6,MATCH($B$12,$P$3:$P$6,0),2),Z$11)))+(AA22*(IF(AA$11="",INDEX($P$3:$Q$6,MATCH($C$12,$P$3:$P$6,0),2),AA$11)))+(AB22*IF(AB$11="",INDEX($P$3:$Q$6,MATCH($D$12,$P$3:$P$6,0),2),AB$11))+(AC22*IF(AC$11="",INDEX($P$3:$Q$6,MATCH($E$12,$P$3:$P$6,0),2),AC$11)))/SUM(Z22:AC22),"") | CJ22: =IFERROR(((AD22*(IF(AD$11="",INDEX($P$3:$Q$6,MATCH($B$12,$P$3:$P$6,0),2),AD$11)))+(AE22*(IF(AE$11="",INDEX($P$3:$Q$6,MATCH($C$12,$P$3:$P$6,0),2),AE$11)))+(AF22*IF(AF$11="",INDEX($P$3:$Q$6,MATCH($D$12,$P$3:$P$6,0),2),AF$11))+(AG22*IF(AG$11="",INDEX($P$3:$Q$6,MATCH($E$12,$P$3:$P$6,0),2),L$11)))/SUM(AD22:AG22),"") | CK22: =IFERROR(((AH22*(IF(AH$11="",INDEX($P$3:$Q$6,MATCH($B$12,$P$3:$P$6,0),2),AH$11)))+(AI22*(IF(AI$11="",INDEX($P$3:$Q$6,MATCH($C$12,$P$3:$P$6,0),2),AI$11)))+(AJ22*IF(AJ$11="",INDEX($P$3:$Q$6,MATCH($D$12,$P$3:$P$6,0),2),AJ$11))+(AK22*IF(AK$11="",INDEX($P$3:$Q$6,MATCH($E$12,$P$3:$P$6,0),2),AK$11)))/SUM(AH22:AK22),"") | CL22: =IFERROR(((AL22*(IF(AL$11="",INDEX($P$3:$Q$6,MATCH($B$12,$P$3:$P$6,0),2),AL$11)))+(AM22*(IF(AM$11="",INDEX($P$3:$Q$6,MATCH($C$12,$P$3:$P$6,0),2),AM$11)))+(AN22*IF(AN$11="",INDEX($P$3:$Q$6,MATCH($D$12,$P$3:$P$6,0),2),AN$11))+(AO22*IF(AO$11="",INDEX($P$3:$Q$6,MATCH($E$12,$P$3:$P$6,0),2),AO$11)))/SUM(AL22:AO22),"") | CM22: =A22 | CN22: =IF(AND(SUM(INDIRECT("CC"&ROW(CC23) - $BI$4&":CC" & ROW(CC22)))=$BI$4,CM22<>""),"Sim","") | CO22: =IF(AND(SUM(INDIRECT("CD"&ROW(CD23) - $BI$4&":CD" & ROW(CD22)))=$BI$4,$CM22<>""),"Sim","") | CP22: =IF(AND(SUM(INDIRECT("CE"&ROW(CE23) - $BI$4&":CE" & ROW(CE22)))=$BI$4,$CM22<>""),"Sim","") | CQ22: =IF(AND(SUM(INDIRECT("CF"&ROW(CF23) - $BI$4&":CF" & ROW(CF22)))=$BI$4,$CM22<>""),"Sim","") | CR22: =IF(AND(SUM(INDIRECT("CG"&ROW(CG23) - $BI$4&":CG" & ROW(CG22)))=$BI$4,$CM22<>""),"Sim","") | CS22: =IF(AND(SUM(INDIRECT("CH"&ROW(CH23) - $BI$4&":CH" & ROW(CH22)))=$BI$4,$CM22<>""),"Sim","") | CT22: =IF(AND(SUM(INDIRECT("CI"&ROW(CI23) - $BI$4&":CI" & ROW(CI22)))=$BI$4,$CM22<>""),"Sim","") | CU22: =IF(AND(SUM(INDIRECT("CJ"&ROW(CJ23) - $BI$4&":CJ" & ROW(CJ22)))=$BI$4,$CM22<>""),"Sim","") | CV22: =IF(AND(SUM(INDIRECT("CK"&ROW(CK23) - $BI$4&":CK" & ROW(CK22)))=$BI$4,$CM22<>""),"Sim","") | CW22: =IF(AND(SUM(INDIRECT("CL"&ROW(CL23) - $BI$4&":CL" & ROW(CL22)))=$BI$4,$CM22<>""),"Sim","") | DB22: =IF(DD22<>"","Out.","") | DC22: 10 | DD22: =IFERROR(__xludf.DUMMYFUNCTION("IFERROR(AVERAGE(FILTER(INDIRECT(ADDRESS(13, (MATCH($BB$4, $12:$12, 0))) & "":"" & ADDRESS(1000, (MATCH($BB$4, $12:$12, 0)))), $DW$13:$DW$500 = DC22,$A$13:$A$500 >= $DQ$25,$A$13:$A$500 <= $DQ$26)),"""") "),"") | DF22: =$AH$10 | DG22: =IFERROR(__xludf.DUMMYFUNCTION("IFERROR(AVERAGE(FILTER(INDIRECT(ADDRESS(13,(MATCH(DF22,$12:$12,0))) & "":"" & ADDRESS(1000, (MATCH(DF22,$12:$12,0)))),$A$13:$A$500 >= $DQ$25,$A$13:$A$500 <= $DQ$26)),"""")"),"") | DI22: =IF(DK22=1,$AH$10,"") | DJ22: =IF(INDEX($CN$10:$CW$12,1,ROW(BV9))="Recurso Adquirido",INDEX($CN$10:$CW$12,1,ROW(BV9)),"") | DK22: =IF(DJ22="Recurso Adquirido",1,"") | DM22: =$AH$10 | DN22: =IFERROR(__xludf.DUMMYFUNCTION("IFERROR(AVERAGE(FILTER(INDIRECT(ADDRESS(13, (MATCH(DM22, $12:$12, 0))) & "":"" & ADDRESS(1000, (MATCH(DM22, $12:$12, 0)))), $A$13:$A$500 > (DATE(YEAR((TODAY()-(30*2))),MONTH((TODAY()-(30*2))),1)))),"""") "),"") | DQ22: =DATE(DP22,1,1) -> 2 | DU22: =A22 | DV22: =ABA!$A22 | DW22: =IF(DV22<>"",MONTH(DV22),"")
